Workbook

Sheet How to read
A1: Patterns / Backtest by tenor / Backtest by period = output_comparison.xlsx (same layout), all numbers are formulas. Valuation 2023 rows first, then 2024.
A2: check = formula sheets minus Python output ('python ...' sheets, pasted from the two Python runs), cell by cell. All zeros = identical.
A4: Detail = one row per method x valuation x accident year x year after valuation (flat table 'Detail', ready for a pivot table).
A5: pattern at valuation tenor / pattern at tenor in year = assumed pattern (from 'pattern input' = Python method output).
A6: expected paid in year = BE at valuation x (pattern(s) - pattern(s-1)) / (1 - pattern(t)); actual paid in year = cum. paid(year) - cum. paid(year-1).
A7: expected cum. paid = paid at valuation + BE x (pattern(s) - pattern(t)) / (1 - pattern(t)); actual cum. paid = cumulative paid in that year.
A8: expected / actual cum. % of U = the same divided by U at valuation (paid + BE at valuation) = the implied actual pattern on the same basis.
A9: Note: expected cum. % of U equals the assumed pattern only if the accident year was exactly on the pattern at valuation (paid / U = pattern(t)).
A11: Backtest by period = SUMIFS over Detail by method, valuation and year (columns 'expected paid in year', 'actual paid in year').
A12: Backtest by tenor = SUMIFS over Detail by method, valuation and tenor in year: sum(cum. paid) / sum(U at valuation), only rows with U > 0.
A13: Pivot example: rows = valuation, AY; columns = year; values = sum of expected paid in year and actual paid in year (filter method).
A15: Metrics = one row per aggregate x method x valuation ('all' pools both valuations), all SUMIFS over Detail. Lower is better.
... A20: rank columns: 1 = best method within the same aggregate and valuation; 'best method' table picks rank 1 per metric.

Sheet Patterns
A1: aggregate | B1: valuation | C1: method | D1: 1 | E1: 2 | F1: 3 | G1: 4 | H1: 5 | I1: 6 | J1: 7 | K1: 8 | L1: 9 | M1: 10 | N1: 11 | O1: 12 | P1: 13 | Q1: 14 | R1: 15 | S1: 16 | T1: 17 | U1: 18 | V1: 19
A2: Example A - method 1 data | B2: 2023 | C2: Method 1 - paid to ultimate | D2: ='pattern input'!B2 -> 0.081890616 | E2: ='pattern input'!C2 -> 0.42095673 | F2: ='pattern input'!D2 -> 0.61058249 | G2: ='pattern input'!E2 -> 0.70360003 | H2: ='pattern input'!F2 -> 0.86468272 | I2: ='pattern input'!G2 -> 0.88394309 | J2: ='pattern input'!H2 -> 0.9002275 | K2: ='pattern input'!I2 -> 0.91433369 | ... U2: ='pattern input'!S2 -> 1
A3: Example A - method 1 data | B3: 2023 | C3: Method 2 - paid to best estimate | D3: ='pattern input'!B4 -> 0.1 | E3: ='pattern input'!C4 -> 0.3688464 | F3: ='pattern input'!D4 -> 0.55622004 | G3: ='pattern input'!E4 -> 0.66306155 | H3: ='pattern input'!F4 -> 0.77507109 | I3: ='pattern input'!G4 -> 0.77507109 | J3: ='pattern input'!H4 -> 0.80663176 | K3: ='pattern input'!I4 -> 0.83397086 | ... U3: ='pattern input'!S4 -> 1
A4: Example A - method 1 data | B4: 2024 | C4: Method 1 - paid to ultimate | D4: ='pattern input'!B3 -> 0.093803567 | E4: ='pattern input'!C3 -> 0.36900849 | F4: ='pattern input'!D3 -> 0.48512488 | G4: ='pattern input'!E3 -> 0.6362617 | H4: ='pattern input'!F3 -> 0.71385313 | I4: ='pattern input'!G3 -> 0.85349634 | J4: ='pattern input'!H3 -> 0.87308863 | K4: ='pattern input'!I3 -> 0.89006025 | ... V4: ='pattern input'!T3 -> 1
A5: Example A - method 1 data | B5: 2024 | C5: Method 2 - paid to best estimate | D5: ='pattern input'!B5 -> 0.1 | E5: ='pattern input'!C5 -> 0.38497852 | F5: ='pattern input'!D5 -> 0.50051044 | G5: ='pattern input'!E5 -> 0.59671347 | H5: ='pattern input'!F5 -> 0.69726286 | I5: ='pattern input'!G5 -> 0.69726286 | J5: ='pattern input'!H5 -> 0.69726286 | K5: ='pattern input'!I5 -> 0.73774733 | ... V5: ='pattern input'!T5 -> 1

Sheet Backtest by tenor
A1: aggregate | B1: valuation | C1: row | D1: 1 | E1: 2 | F1: 3 | G1: 4 | H1: 5 | I1: 6 | J1: 7 | K1: 8 | L1: 9 | M1: 10 | N1: 11 | O1: 12 | P1: 13 | Q1: 14 | R1: 15 | S1: 16 | T1: 17 | U1: 18 | V1: 19
A2: Example A - method 1 data | B2: 2023 | C2: actual | D2: =IF(D3="","",SUMIFS(Detail!$Q$2:$Q$105,Detail!$A$2:$A$105,"M1",Detail!$B$2:$B$105,$B2,Detail!$G$2:$G$105,D$1,Detail!$J$2:$J$105,">0")/SUMIFS(Detail!$J$2:$J$105,Detail!$A$2:$A$105,"M1",Detail!$B$2:$B$105,$B2,Detail!$G$2:$G$105,D$1,Detail!$J$2:$J$105,">0")) | E2: =IF(E3="","",SUMIFS(Detail!$Q$2:$Q$105,Detail!$A$2:$A$105,"M1",Detail!$B$2:$B$105,$B2,Detail!$G$2:$G$105,E$1,Detail!$J$2:$J$105,">0")/SUMIFS(Detail!$J$2:$J$105,Detail!$A$2:$A$105,"M1",Detail!$B$2:$B$105,$B2,Detail!$G$2:$G$105,E$1,Detail!$J$2:$J$105,">0")) -> 0.25676451 | F2: =IF(F3="","",SUMIFS(Detail!$Q$2:$Q$105,Detail!$A$2:$A$105,"M1",Detail!$B$2:$B$105,$B2,Detail!$G$2:$G$105,F$1,Detail!$J$2:$J$105,">0")/SUMIFS(Detail!$J$2:$J$105,Detail!$A$2:$A$105,"M1",Detail!$B$2:$B$105,$B2,Detail!$G$2:$G$105,F$1,Detail!$J$2:$J$105,">0")) -> 0.21095107 | G2: =IF(G3="","",SUMIFS(Detail!$Q$2:$Q$105,Detail!$A$2:$A$105,"M1",Detail!$B$2:$B$105,$B2,Detail!$G$2:$G$105,G$1,Detail!$J$2:$J$105,">0")/SUMIFS(Detail!$J$2:$J$105,Detail!$A$2:$A$105,"M1",Detail!$B$2:$B$105,$B2,Detail!$G$2:$G$105,G$1,Detail!$J$2:$J$105,">0")) -> 0.43624068 | H2: =IF(H3="","",SUMIFS(Detail!$Q$2:$Q$105,Detail!$A$2:$A$105,"M1",Detail!$B$2:$B$105,$B2,Detail!$G$2:$G$105,H$1,Detail!$J$2:$J$105,">0")/SUMIFS(Detail!$J$2:$J$105,Detail!$A$2:$A$105,"M1",Detail!$B$2:$B$105,$B2,Detail!$G$2:$G$105,H$1,Detail!$J$2:$J$105,">0")) -> 0.61851556 | I2: =IF(I3="","",SUMIFS(Detail!$Q$2:$Q$105,Detail!$A$2:$A$105,"M1",Detail!$B$2:$B$105,$B2,Detail!$G$2:$G$105,I$1,Detail!$J$2:$J$105,">0")/SUMIFS(Detail!$J$2:$J$105,Detail!$A$2:$A$105,"M1",Detail!$B$2:$B$105,$B2,Detail!$G$2:$G$105,I$1,Detail!$J$2:$J$105,">0")) -> 0.73858203 | J2: =IF(J3="","",SUMIFS(Detail!$Q$2:$Q$105,Detail!$A$2:$A$105,"M1",Detail!$B$2:$B$105,$B2,Detail!$G$2:$G$105,J$1,Detail!$J$2:$J$105,">0")/SUMIFS(Detail!$J$2:$J$105,Detail!$A$2:$A$105,"M1",Detail!$B$2:$B$105,$B2,Detail!$G$2:$G$105,J$1,Detail!$J$2:$J$105,">0")) -> 0.92597426 | K2: =IF(K3="","",SUMIFS(Detail!$Q$2:$Q$105,Detail!$A$2:$A$105,"M1",Detail!$B$2:$B$105,$B2,Detail!$G$2:$G$105,K$1,Detail!$J$2:$J$105,">0")/SUMIFS(Detail!$J$2:$J$105,Detail!$A$2:$A$105,"M1",Detail!$B$2:$B$105,$B2,Detail!$G$2:$G$105,K$1,Detail!$J$2:$J$105,">0")) -> 0.91482326 | ... V2: =IF(V3="","",SUMIFS(Detail!$Q$2:$Q$105,Detail!$A$2:$A$105,"M1",Detail!$B$2:$B$105,$B2,Detail!$G$2:$G$105,V$1,Detail!$J$2:$J$105,">0")/SUMIFS(Detail!$J$2:$J$105,Detail!$A$2:$A$105,"M1",Detail!$B$2:$B$105,$B2,Detail!$G$2:$G$105,V$1,Detail!$J$2:$J$105,">0")) -> 1
A3: Example A - method 1 data | B3: 2023 | C3: accident periods | D3: =IF(COUNTIFS(Detail!$A$2:$A$105,"M1",Detail!$B$2:$B$105,$B2,Detail!$G$2:$G$105,D$1,Detail!$J$2:$J$105,">0")=0,"",COUNTIFS(Detail!$A$2:$A$105,"M1",Detail!$B$2:$B$105,$B2,Detail!$G$2:$G$105,D$1,Detail!$J$2:$J$105,">0")) | E3: =IF(COUNTIFS(Detail!$A$2:$A$105,"M1",Detail!$B$2:$B$105,$B2,Detail!$G$2:$G$105,E$1,Detail!$J$2:$J$105,">0")=0,"",COUNTIFS(Detail!$A$2:$A$105,"M1",Detail!$B$2:$B$105,$B2,Detail!$G$2:$G$105,E$1,Detail!$J$2:$J$105,">0")) -> 1 | F3: =IF(COUNTIFS(Detail!$A$2:$A$105,"M1",Detail!$B$2:$B$105,$B2,Detail!$G$2:$G$105,F$1,Detail!$J$2:$J$105,">0")=0,"",COUNTIFS(Detail!$A$2:$A$105,"M1",Detail!$B$2:$B$105,$B2,Detail!$G$2:$G$105,F$1,Detail!$J$2:$J$105,">0")) -> 2 | G3: =IF(COUNTIFS(Detail!$A$2:$A$105,"M1",Detail!$B$2:$B$105,$B2,Detail!$G$2:$G$105,G$1,Detail!$J$2:$J$105,">0")=0,"",COUNTIFS(Detail!$A$2:$A$105,"M1",Detail!$B$2:$B$105,$B2,Detail!$G$2:$G$105,G$1,Detail!$J$2:$J$105,">0")) -> 2 | H3: =IF(COUNTIFS(Detail!$A$2:$A$105,"M1",Detail!$B$2:$B$105,$B2,Detail!$G$2:$G$105,H$1,Detail!$J$2:$J$105,">0")=0,"",COUNTIFS(Detail!$A$2:$A$105,"M1",Detail!$B$2:$B$105,$B2,Detail!$G$2:$G$105,H$1,Detail!$J$2:$J$105,">0")) -> 2 | I3: =IF(COUNTIFS(Detail!$A$2:$A$105,"M1",Detail!$B$2:$B$105,$B2,Detail!$G$2:$G$105,I$1,Detail!$J$2:$J$105,">0")=0,"",COUNTIFS(Detail!$A$2:$A$105,"M1",Detail!$B$2:$B$105,$B2,Detail!$G$2:$G$105,I$1,Detail!$J$2:$J$105,">0")) -> 2 | J3: =IF(COUNTIFS(Detail!$A$2:$A$105,"M1",Detail!$B$2:$B$105,$B2,Detail!$G$2:$G$105,J$1,Detail!$J$2:$J$105,">0")=0,"",COUNTIFS(Detail!$A$2:$A$105,"M1",Detail!$B$2:$B$105,$B2,Detail!$G$2:$G$105,J$1,Detail!$J$2:$J$105,">0")) -> 2 | K3: =IF(COUNTIFS(Detail!$A$2:$A$105,"M1",Detail!$B$2:$B$105,$B2,Detail!$G$2:$G$105,K$1,Detail!$J$2:$J$105,">0")=0,"",COUNTIFS(Detail!$A$2:$A$105,"M1",Detail!$B$2:$B$105,$B2,Detail!$G$2:$G$105,K$1,Detail!$J$2:$J$105,">0")) -> 2 | ... V3: =IF(COUNTIFS(Detail!$A$2:$A$105,"M1",Detail!$B$2:$B$105,$B2,Detail!$G$2:$G$105,V$1,Detail!$J$2:$J$105,">0")=0,"",COUNTIFS(Detail!$A$2:$A$105,"M1",Detail!$B$2:$B$105,$B2,Detail!$G$2:$G$105,V$1,Detail!$J$2:$J$105,">0")) -> 1
A4: Example A - method 1 data | B4: 2023 | C4: expected M1 | D4: =IF(D3="","",SUMIFS(Detail!$P$2:$P$105,Detail!$A$2:$A$105,"M1",Detail!$B$2:$B$105,$B2,Detail!$G$2:$G$105,D$1,Detail!$J$2:$J$105,">0")/SUMIFS(Detail!$J$2:$J$105,Detail!$A$2:$A$105,"M1",Detail!$B$2:$B$105,$B2,Detail!$G$2:$G$105,D$1,Detail!$J$2:$J$105,">0")) | E4: =IF(E3="","",SUMIFS(Detail!$P$2:$P$105,Detail!$A$2:$A$105,"M1",Detail!$B$2:$B$105,$B2,Detail!$G$2:$G$105,E$1,Detail!$J$2:$J$105,">0")/SUMIFS(Detail!$J$2:$J$105,Detail!$A$2:$A$105,"M1",Detail!$B$2:$B$105,$B2,Detail!$G$2:$G$105,E$1,Detail!$J$2:$J$105,">0")) -> 0.37080488 | F4: =IF(F3="","",SUMIFS(Detail!$P$2:$P$105,Detail!$A$2:$A$105,"M1",Detail!$B$2:$B$105,$B2,Detail!$G$2:$G$105,F$1,Detail!$J$2:$J$105,">0")/SUMIFS(Detail!$J$2:$J$105,Detail!$A$2:$A$105,"M1",Detail!$B$2:$B$105,$B2,Detail!$G$2:$G$105,F$1,Detail!$J$2:$J$105,">0")) -> 0.5122228 | G4: =IF(G3="","",SUMIFS(Detail!$P$2:$P$105,Detail!$A$2:$A$105,"M1",Detail!$B$2:$B$105,$B2,Detail!$G$2:$G$105,G$1,Detail!$J$2:$J$105,">0")/SUMIFS(Detail!$J$2:$J$105,Detail!$A$2:$A$105,"M1",Detail!$B$2:$B$105,$B2,Detail!$G$2:$G$105,G$1,Detail!$J$2:$J$105,">0")) -> 0.63029661 | H4: =IF(H3="","",SUMIFS(Detail!$P$2:$P$105,Detail!$A$2:$A$105,"M1",Detail!$B$2:$B$105,$B2,Detail!$G$2:$G$105,H$1,Detail!$J$2:$J$105,">0")/SUMIFS(Detail!$J$2:$J$105,Detail!$A$2:$A$105,"M1",Detail!$B$2:$B$105,$B2,Detail!$G$2:$G$105,H$1,Detail!$J$2:$J$105,">0")) -> 0.85367748 | I4: =IF(I3="","",SUMIFS(Detail!$P$2:$P$105,Detail!$A$2:$A$105,"M1",Detail!$B$2:$B$105,$B2,Detail!$G$2:$G$105,I$1,Detail!$J$2:$J$105,">0")/SUMIFS(Detail!$J$2:$J$105,Detail!$A$2:$A$105,"M1",Detail!$B$2:$B$105,$B2,Detail!$G$2:$G$105,I$1,Detail!$J$2:$J$105,">0")) -> 0.89310858 | J4: =IF(J3="","",SUMIFS(Detail!$P$2:$P$105,Detail!$A$2:$A$105,"M1",Detail!$B$2:$B$105,$B2,Detail!$G$2:$G$105,J$1,Detail!$J$2:$J$105,">0")/SUMIFS(Detail!$J$2:$J$105,Detail!$A$2:$A$105,"M1",Detail!$B$2:$B$105,$B2,Detail!$G$2:$G$105,J$1,Detail!$J$2:$J$105,">0")) -> 0.94264491 | K4: =IF(K3="","",SUMIFS(Detail!$P$2:$P$105,Detail!$A$2:$A$105,"M1",Detail!$B$2:$B$105,$B2,Detail!$G$2:$G$105,K$1,Detail!$J$2:$J$105,">0")/SUMIFS(Detail!$J$2:$J$105,Detail!$A$2:$A$105,"M1",Detail!$B$2:$B$105,$B2,Detail!$G$2:$G$105,K$1,Detail!$J$2:$J$105,">0")) -> 0.9371276 | ... V4: =IF(V3="","",SUMIFS(Detail!$P$2:$P$105,Detail!$A$2:$A$105,"M1",Detail!$B$2:$B$105,$B2,Detail!$G$2:$G$105,V$1,Detail!$J$2:$J$105,">0")/SUMIFS(Detail!$J$2:$J$105,Detail!$A$2:$A$105,"M1",Detail!$B$2:$B$105,$B2,Detail!$G$2:$G$105,V$1,Detail!$J$2:$J$105,">0")) -> 1
A5: Example A - method 1 data | B5: 2023 | C5: difference M1 | D5: =IF(D3="","",D4-D2) | E5: =IF(E3="","",E4-E2) -> 0.11404037 | F5: =IF(F3="","",F4-F2) -> 0.30127174 | G5: =IF(G3="","",G4-G2) -> 0.19405593 | H5: =IF(H3="","",H4-H2) -> 0.23516192 | I5: =IF(I3="","",I4-I2) -> 0.15452654 | J5: =IF(J3="","",J4-J2) -> 0.016670649 | K5: =IF(K3="","",K4-K2) -> 0.022304339 | ... V5: =IF(V3="","",V4-V2) -> 0
A6: Example A - method 1 data | B6: 2023 | C6: expected M2 | D6: =IF(D3="","",SUMIFS(Detail!$P$2:$P$105,Detail!$A$2:$A$105,"M2",Detail!$B$2:$B$105,$B2,Detail!$G$2:$G$105,D$1,Detail!$J$2:$J$105,">0")/SUMIFS(Detail!$J$2:$J$105,Detail!$A$2:$A$105,"M2",Detail!$B$2:$B$105,$B2,Detail!$G$2:$G$105,D$1,Detail!$J$2:$J$105,">0")) | E6: =IF(E3="","",SUMIFS(Detail!$P$2:$P$105,Detail!$A$2:$A$105,"M2",Detail!$B$2:$B$105,$B2,Detail!$G$2:$G$105,E$1,Detail!$J$2:$J$105,">0")/SUMIFS(Detail!$J$2:$J$105,Detail!$A$2:$A$105,"M2",Detail!$B$2:$B$105,$B2,Detail!$G$2:$G$105,E$1,Detail!$J$2:$J$105,">0")) -> 0.30038147 | F6: =IF(F3="","",SUMIFS(Detail!$P$2:$P$105,Detail!$A$2:$A$105,"M2",Detail!$B$2:$B$105,$B2,Detail!$G$2:$G$105,F$1,Detail!$J$2:$J$105,">0")/SUMIFS(Detail!$J$2:$J$105,Detail!$A$2:$A$105,"M2",Detail!$B$2:$B$105,$B2,Detail!$G$2:$G$105,F$1,Detail!$J$2:$J$105,">0")) -> 0.45783176 | G6: =IF(G3="","",SUMIFS(Detail!$P$2:$P$105,Detail!$A$2:$A$105,"M2",Detail!$B$2:$B$105,$B2,Detail!$G$2:$G$105,G$1,Detail!$J$2:$J$105,">0")/SUMIFS(Detail!$J$2:$J$105,Detail!$A$2:$A$105,"M2",Detail!$B$2:$B$105,$B2,Detail!$G$2:$G$105,G$1,Detail!$J$2:$J$105,">0")) -> 0.62505988 | H6: =IF(H3="","",SUMIFS(Detail!$P$2:$P$105,Detail!$A$2:$A$105,"M2",Detail!$B$2:$B$105,$B2,Detail!$G$2:$G$105,H$1,Detail!$J$2:$J$105,">0")/SUMIFS(Detail!$J$2:$J$105,Detail!$A$2:$A$105,"M2",Detail!$B$2:$B$105,$B2,Detail!$G$2:$G$105,H$1,Detail!$J$2:$J$105,">0")) -> 0.786363 | I6: =IF(I3="","",SUMIFS(Detail!$P$2:$P$105,Detail!$A$2:$A$105,"M2",Detail!$B$2:$B$105,$B2,Detail!$G$2:$G$105,I$1,Detail!$J$2:$J$105,">0")/SUMIFS(Detail!$J$2:$J$105,Detail!$A$2:$A$105,"M2",Detail!$B$2:$B$105,$B2,Detail!$G$2:$G$105,I$1,Detail!$J$2:$J$105,">0")) -> 0.82225388 | J6: =IF(J3="","",SUMIFS(Detail!$P$2:$P$105,Detail!$A$2:$A$105,"M2",Detail!$B$2:$B$105,$B2,Detail!$G$2:$G$105,J$1,Detail!$J$2:$J$105,">0")/SUMIFS(Detail!$J$2:$J$105,Detail!$A$2:$A$105,"M2",Detail!$B$2:$B$105,$B2,Detail!$G$2:$G$105,J$1,Detail!$J$2:$J$105,">0")) -> 0.93636111 | K6: =IF(K3="","",SUMIFS(Detail!$P$2:$P$105,Detail!$A$2:$A$105,"M2",Detail!$B$2:$B$105,$B2,Detail!$G$2:$G$105,K$1,Detail!$J$2:$J$105,">0")/SUMIFS(Detail!$J$2:$J$105,Detail!$A$2:$A$105,"M2",Detail!$B$2:$B$105,$B2,Detail!$G$2:$G$105,K$1,Detail!$J$2:$J$105,">0")) -> 0.9371276 | ... V6: =IF(V3="","",SUMIFS(Detail!$P$2:$P$105,Detail!$A$2:$A$105,"M2",Detail!$B$2:$B$105,$B2,Detail!$G$2:$G$105,V$1,Detail!$J$2:$J$105,">0")/SUMIFS(Detail!$J$2:$J$105,Detail!$A$2:$A$105,"M2",Detail!$B$2:$B$105,$B2,Detail!$G$2:$G$105,V$1,Detail!$J$2:$J$105,">0")) -> 1
A7: Example A - method 1 data | B7: 2023 | C7: difference M2 | D7: =IF(D3="","",D6-D2) | E7: =IF(E3="","",E6-E2) -> 0.04361696 | F7: =IF(F3="","",F6-F2) -> 0.24688069 | G7: =IF(G3="","",G6-G2) -> 0.1888192 | H7: =IF(H3="","",H6-H2) -> 0.16784744 | I7: =IF(I3="","",I6-I2) -> 0.083671841 | J7: =IF(J3="","",J6-J2) -> 0.010386847 | K7: =IF(K3="","",K6-K2) -> 0.022304339 | ... V7: =IF(V3="","",V6-V2) -> 0
A10: Example A - method 1 data | B10: 2024 | C10: actual | D10: =IF(D11="","",SUMIFS(Detail!$Q$2:$Q$105,Detail!$A$2:$A$105,"M1",Detail!$B$2:$B$105,$B10,Detail!$G$2:$G$105,D$1,Detail!$J$2:$J$105,">0")/SUMIFS(Detail!$J$2:$J$105,Detail!$A$2:$A$105,"M1",Detail!$B$2:$B$105,$B10,Detail!$G$2:$G$105,D$1,Detail!$J$2:$J$105,">0")) | E10: =IF(E11="","",SUMIFS(Detail!$Q$2:$Q$105,Detail!$A$2:$A$105,"M1",Detail!$B$2:$B$105,$B10,Detail!$G$2:$G$105,E$1,Detail!$J$2:$J$105,">0")/SUMIFS(Detail!$J$2:$J$105,Detail!$A$2:$A$105,"M1",Detail!$B$2:$B$105,$B10,Detail!$G$2:$G$105,E$1,Detail!$J$2:$J$105,">0")) -> 0.76791054 | F10: =IF(F11="","",SUMIFS(Detail!$Q$2:$Q$105,Detail!$A$2:$A$105,"M1",Detail!$B$2:$B$105,$B10,Detail!$G$2:$G$105,F$1,Detail!$J$2:$J$105,">0")/SUMIFS(Detail!$J$2:$J$105,Detail!$A$2:$A$105,"M1",Detail!$B$2:$B$105,$B10,Detail!$G$2:$G$105,F$1,Detail!$J$2:$J$105,">0")) -> 0.23335979 | G10: =IF(G11="","",SUMIFS(Detail!$Q$2:$Q$105,Detail!$A$2:$A$105,"M1",Detail!$B$2:$B$105,$B10,Detail!$G$2:$G$105,G$1,Detail!$J$2:$J$105,">0")/SUMIFS(Detail!$J$2:$J$105,Detail!$A$2:$A$105,"M1",Detail!$B$2:$B$105,$B10,Detail!$G$2:$G$105,G$1,Detail!$J$2:$J$105,">0")) -> 0.15934462 | H10: =IF(H11="","",SUMIFS(Detail!$Q$2:$Q$105,Detail!$A$2:$A$105,"M1",Detail!$B$2:$B$105,$B10,Detail!$G$2:$G$105,H$1,Detail!$J$2:$J$105,">0")/SUMIFS(Detail!$J$2:$J$105,Detail!$A$2:$A$105,"M1",Detail!$B$2:$B$105,$B10,Detail!$G$2:$G$105,H$1,Detail!$J$2:$J$105,">0")) -> 0.59330775 | I10: =IF(I11="","",SUMIFS(Detail!$Q$2:$Q$105,Detail!$A$2:$A$105,"M1",Detail!$B$2:$B$105,$B10,Detail!$G$2:$G$105,I$1,Detail!$J$2:$J$105,">0")/SUMIFS(Detail!$J$2:$J$105,Detail!$A$2:$A$105,"M1",Detail!$B$2:$B$105,$B10,Detail!$G$2:$G$105,I$1,Detail!$J$2:$J$105,">0")) -> 0.70633565 | J10: =IF(J11="","",SUMIFS(Detail!$Q$2:$Q$105,Detail!$A$2:$A$105,"M1",Detail!$B$2:$B$105,$B10,Detail!$G$2:$G$105,J$1,Detail!$J$2:$J$105,">0")/SUMIFS(Detail!$J$2:$J$105,Detail!$A$2:$A$105,"M1",Detail!$B$2:$B$105,$B10,Detail!$G$2:$G$105,J$1,Detail!$J$2:$J$105,">0")) -> 0.95243746 | K10: =IF(K11="","",SUMIFS(Detail!$Q$2:$Q$105,Detail!$A$2:$A$105,"M1",Detail!$B$2:$B$105,$B10,Detail!$G$2:$G$105,K$1,Detail!$J$2:$J$105,">0")/SUMIFS(Detail!$J$2:$J$105,Detail!$A$2:$A$105,"M1",Detail!$B$2:$B$105,$B10,Detail!$G$2:$G$105,K$1,Detail!$J$2:$J$105,">0")) -> 0.67208333 | ... V10: =IF(V11="","",SUMIFS(Detail!$Q$2:$Q$105,Detail!$A$2:$A$105,"M1",Detail!$B$2:$B$105,$B10,Detail!$G$2:$G$105,V$1,Detail!$J$2:$J$105,">0")/SUMIFS(Detail!$J$2:$J$105,Detail!$A$2:$A$105,"M1",Detail!$B$2:$B$105,$B10,Detail!$G$2:$G$105,V$1,Detail!$J$2:$J$105,">0")) -> 1
A11: Example A - method 1 data | B11: 2024 | C11: accident periods | D11: =IF(COUNTIFS(Detail!$A$2:$A$105,"M1",Detail!$B$2:$B$105,$B10,Detail!$G$2:$G$105,D$1,Detail!$J$2:$J$105,">0")=0,"",COUNTIFS(Detail!$A$2:$A$105,"M1",Detail!$B$2:$B$105,$B10,Detail!$G$2:$G$105,D$1,Detail!$J$2:$J$105,">0")) | E11: =IF(COUNTIFS(Detail!$A$2:$A$105,"M1",Detail!$B$2:$B$105,$B10,Detail!$G$2:$G$105,E$1,Detail!$J$2:$J$105,">0")=0,"",COUNTIFS(Detail!$A$2:$A$105,"M1",Detail!$B$2:$B$105,$B10,Detail!$G$2:$G$105,E$1,Detail!$J$2:$J$105,">0")) -> 1 | F11: =IF(COUNTIFS(Detail!$A$2:$A$105,"M1",Detail!$B$2:$B$105,$B10,Detail!$G$2:$G$105,F$1,Detail!$J$2:$J$105,">0")=0,"",COUNTIFS(Detail!$A$2:$A$105,"M1",Detail!$B$2:$B$105,$B10,Detail!$G$2:$G$105,F$1,Detail!$J$2:$J$105,">0")) -> 1 | G11: =IF(COUNTIFS(Detail!$A$2:$A$105,"M1",Detail!$B$2:$B$105,$B10,Detail!$G$2:$G$105,G$1,Detail!$J$2:$J$105,">0")=0,"",COUNTIFS(Detail!$A$2:$A$105,"M1",Detail!$B$2:$B$105,$B10,Detail!$G$2:$G$105,G$1,Detail!$J$2:$J$105,">0")) -> 1 | H11: =IF(COUNTIFS(Detail!$A$2:$A$105,"M1",Detail!$B$2:$B$105,$B10,Detail!$G$2:$G$105,H$1,Detail!$J$2:$J$105,">0")=0,"",COUNTIFS(Detail!$A$2:$A$105,"M1",Detail!$B$2:$B$105,$B10,Detail!$G$2:$G$105,H$1,Detail!$J$2:$J$105,">0")) -> 1 | I11: =IF(COUNTIFS(Detail!$A$2:$A$105,"M1",Detail!$B$2:$B$105,$B10,Detail!$G$2:$G$105,I$1,Detail!$J$2:$J$105,">0")=0,"",COUNTIFS(Detail!$A$2:$A$105,"M1",Detail!$B$2:$B$105,$B10,Detail!$G$2:$G$105,I$1,Detail!$J$2:$J$105,">0")) -> 1 | J11: =IF(COUNTIFS(Detail!$A$2:$A$105,"M1",Detail!$B$2:$B$105,$B10,Detail!$G$2:$G$105,J$1,Detail!$J$2:$J$105,">0")=0,"",COUNTIFS(Detail!$A$2:$A$105,"M1",Detail!$B$2:$B$105,$B10,Detail!$G$2:$G$105,J$1,Detail!$J$2:$J$105,">0")) -> 1 | K11: =IF(COUNTIFS(Detail!$A$2:$A$105,"M1",Detail!$B$2:$B$105,$B10,Detail!$G$2:$G$105,K$1,Detail!$J$2:$J$105,">0")=0,"",COUNTIFS(Detail!$A$2:$A$105,"M1",Detail!$B$2:$B$105,$B10,Detail!$G$2:$G$105,K$1,Detail!$J$2:$J$105,">0")) -> 1 | ... V11: =IF(COUNTIFS(Detail!$A$2:$A$105,"M1",Detail!$B$2:$B$105,$B10,Detail!$G$2:$G$105,V$1,Detail!$J$2:$J$105,">0")=0,"",COUNTIFS(Detail!$A$2:$A$105,"M1",Detail!$B$2:$B$105,$B10,Detail!$G$2:$G$105,V$1,Detail!$J$2:$J$105,">0")) -> 1
A12: Example A - method 1 data | B12: 2024 | C12: expected M1 | D12: =IF(D11="","",SUMIFS(Detail!$P$2:$P$105,Detail!$A$2:$A$105,"M1",Detail!$B$2:$B$105,$B10,Detail!$G$2:$G$105,D$1,Detail!$J$2:$J$105,">0")/SUMIFS(Detail!$J$2:$J$105,Detail!$A$2:$A$105,"M1",Detail!$B$2:$B$105,$B10,Detail!$G$2:$G$105,D$1,Detail!$J$2:$J$105,">0")) | E12: =IF(E11="","",SUMIFS(Detail!$P$2:$P$105,Detail!$A$2:$A$105,"M1",Detail!$B$2:$B$105,$B10,Detail!$G$2:$G$105,E$1,Detail!$J$2:$J$105,">0")/SUMIFS(Detail!$J$2:$J$105,Detail!$A$2:$A$105,"M1",Detail!$B$2:$B$105,$B10,Detail!$G$2:$G$105,E$1,Detail!$J$2:$J$105,">0")) -> 0.8383038 | F12: =IF(F11="","",SUMIFS(Detail!$P$2:$P$105,Detail!$A$2:$A$105,"M1",Detail!$B$2:$B$105,$B10,Detail!$G$2:$G$105,F$1,Detail!$J$2:$J$105,">0")/SUMIFS(Detail!$J$2:$J$105,Detail!$A$2:$A$105,"M1",Detail!$B$2:$B$105,$B10,Detail!$G$2:$G$105,F$1,Detail!$J$2:$J$105,">0")) -> 0.37443855 | G12: =IF(G11="","",SUMIFS(Detail!$P$2:$P$105,Detail!$A$2:$A$105,"M1",Detail!$B$2:$B$105,$B10,Detail!$G$2:$G$105,G$1,Detail!$J$2:$J$105,">0")/SUMIFS(Detail!$J$2:$J$105,Detail!$A$2:$A$105,"M1",Detail!$B$2:$B$105,$B10,Detail!$G$2:$G$105,G$1,Detail!$J$2:$J$105,">0")) -> 0.40611121 | H12: =IF(H11="","",SUMIFS(Detail!$P$2:$P$105,Detail!$A$2:$A$105,"M1",Detail!$B$2:$B$105,$B10,Detail!$G$2:$G$105,H$1,Detail!$J$2:$J$105,">0")/SUMIFS(Detail!$J$2:$J$105,Detail!$A$2:$A$105,"M1",Detail!$B$2:$B$105,$B10,Detail!$G$2:$G$105,H$1,Detail!$J$2:$J$105,">0")) -> 0.68006198 | I12: =IF(I11="","",SUMIFS(Detail!$P$2:$P$105,Detail!$A$2:$A$105,"M1",Detail!$B$2:$B$105,$B10,Detail!$G$2:$G$105,I$1,Detail!$J$2:$J$105,">0")/SUMIFS(Detail!$J$2:$J$105,Detail!$A$2:$A$105,"M1",Detail!$B$2:$B$105,$B10,Detail!$G$2:$G$105,I$1,Detail!$J$2:$J$105,">0")) -> 0.84964748 | J12: =IF(J11="","",SUMIFS(Detail!$P$2:$P$105,Detail!$A$2:$A$105,"M1",Detail!$B$2:$B$105,$B10,Detail!$G$2:$G$105,J$1,Detail!$J$2:$J$105,">0")/SUMIFS(Detail!$J$2:$J$105,Detail!$A$2:$A$105,"M1",Detail!$B$2:$B$105,$B10,Detail!$G$2:$G$105,J$1,Detail!$J$2:$J$105,">0")) -> 0.95879811 | K12: =IF(K11="","",SUMIFS(Detail!$P$2:$P$105,Detail!$A$2:$A$105,"M1",Detail!$B$2:$B$105,$B10,Detail!$G$2:$G$105,K$1,Detail!$J$2:$J$105,">0")/SUMIFS(Detail!$J$2:$J$105,Detail!$A$2:$A$105,"M1",Detail!$B$2:$B$105,$B10,Detail!$G$2:$G$105,K$1,Detail!$J$2:$J$105,">0")) -> 0.71593502 | ... V12: =IF(V11="","",SUMIFS(Detail!$P$2:$P$105,Detail!$A$2:$A$105,"M1",Detail!$B$2:$B$105,$B10,Detail!$G$2:$G$105,V$1,Detail!$J$2:$J$105,">0")/SUMIFS(Detail!$J$2:$J$105,Detail!$A$2:$A$105,"M1",Detail!$B$2:$B$105,$B10,Detail!$G$2:$G$105,V$1,Detail!$J$2:$J$105,">0")) -> 1
A13: Example A - method 1 data | B13: 2024 | C13: difference M1 | D13: =IF(D11="","",D12-D10) | E13: =IF(E11="","",E12-E10) -> 0.070393256 | F13: =IF(F11="","",F12-F10) -> 0.14107875 | G13: =IF(G11="","",G12-G10) -> 0.24676659 | H13: =IF(H11="","",H12-H10) -> 0.086754225 | I13: =IF(I11="","",I12-I10) -> 0.14331183 | J13: =IF(J11="","",J12-J10) -> 0.0063606565 | K13: =IF(K11="","",K12-K10) -> 0.043851682 | ... V13: =IF(V11="","",V12-V10) -> 0
A14: Example A - method 1 data | B14: 2024 | C14: expected M2 | D14: =IF(D11="","",SUMIFS(Detail!$P$2:$P$105,Detail!$A$2:$A$105,"M2",Detail!$B$2:$B$105,$B10,Detail!$G$2:$G$105,D$1,Detail!$J$2:$J$105,">0")/SUMIFS(Detail!$J$2:$J$105,Detail!$A$2:$A$105,"M2",Detail!$B$2:$B$105,$B10,Detail!$G$2:$G$105,D$1,Detail!$J$2:$J$105,">0")) | E14: =IF(E11="","",SUMIFS(Detail!$P$2:$P$105,Detail!$A$2:$A$105,"M2",Detail!$B$2:$B$105,$B10,Detail!$G$2:$G$105,E$1,Detail!$J$2:$J$105,">0")/SUMIFS(Detail!$J$2:$J$105,Detail!$A$2:$A$105,"M2",Detail!$B$2:$B$105,$B10,Detail!$G$2:$G$105,E$1,Detail!$J$2:$J$105,">0")) -> 0.84131115 | F14: =IF(F11="","",SUMIFS(Detail!$P$2:$P$105,Detail!$A$2:$A$105,"M2",Detail!$B$2:$B$105,$B10,Detail!$G$2:$G$105,F$1,Detail!$J$2:$J$105,">0")/SUMIFS(Detail!$J$2:$J$105,Detail!$A$2:$A$105,"M2",Detail!$B$2:$B$105,$B10,Detail!$G$2:$G$105,F$1,Detail!$J$2:$J$105,">0")) -> 0.37737333 | G14: =IF(G11="","",SUMIFS(Detail!$P$2:$P$105,Detail!$A$2:$A$105,"M2",Detail!$B$2:$B$105,$B10,Detail!$G$2:$G$105,G$1,Detail!$J$2:$J$105,">0")/SUMIFS(Detail!$J$2:$J$105,Detail!$A$2:$A$105,"M2",Detail!$B$2:$B$105,$B10,Detail!$G$2:$G$105,G$1,Detail!$J$2:$J$105,">0")) -> 0.32125709 | H14: =IF(H11="","",SUMIFS(Detail!$P$2:$P$105,Detail!$A$2:$A$105,"M2",Detail!$B$2:$B$105,$B10,Detail!$G$2:$G$105,H$1,Detail!$J$2:$J$105,">0")/SUMIFS(Detail!$J$2:$J$105,Detail!$A$2:$A$105,"M2",Detail!$B$2:$B$105,$B10,Detail!$G$2:$G$105,H$1,Detail!$J$2:$J$105,">0")) -> 0.69470627 | I14: =IF(I11="","",SUMIFS(Detail!$P$2:$P$105,Detail!$A$2:$A$105,"M2",Detail!$B$2:$B$105,$B10,Detail!$G$2:$G$105,I$1,Detail!$J$2:$J$105,">0")/SUMIFS(Detail!$J$2:$J$105,Detail!$A$2:$A$105,"M2",Detail!$B$2:$B$105,$B10,Detail!$G$2:$G$105,I$1,Detail!$J$2:$J$105,">0")) -> 0.70633565 | J14: =IF(J11="","",SUMIFS(Detail!$P$2:$P$105,Detail!$A$2:$A$105,"M2",Detail!$B$2:$B$105,$B10,Detail!$G$2:$G$105,J$1,Detail!$J$2:$J$105,">0")/SUMIFS(Detail!$J$2:$J$105,Detail!$A$2:$A$105,"M2",Detail!$B$2:$B$105,$B10,Detail!$G$2:$G$105,J$1,Detail!$J$2:$J$105,">0")) -> 0.95243746 | K14: =IF(K11="","",SUMIFS(Detail!$P$2:$P$105,Detail!$A$2:$A$105,"M2",Detail!$B$2:$B$105,$B10,Detail!$G$2:$G$105,K$1,Detail!$J$2:$J$105,">0")/SUMIFS(Detail!$J$2:$J$105,Detail!$A$2:$A$105,"M2",Detail!$B$2:$B$105,$B10,Detail!$G$2:$G$105,K$1,Detail!$J$2:$J$105,">0")) -> 0.71593502 | ... V14: =IF(V11="","",SUMIFS(Detail!$P$2:$P$105,Detail!$A$2:$A$105,"M2",Detail!$B$2:$B$105,$B10,Detail!$G$2:$G$105,V$1,Detail!$J$2:$J$105,">0")/SUMIFS(Detail!$J$2:$J$105,Detail!$A$2:$A$105,"M2",Detail!$B$2:$B$105,$B10,Detail!$G$2:$G$105,V$1,Detail!$J$2:$J$105,">0")) -> 1
A15: Example A - method 1 data | B15: 2024 | C15: difference M2 | D15: =IF(D11="","",D14-D10) | E15: =IF(E11="","",E14-E10) -> 0.073400604 | F15: =IF(F11="","",F14-F10) -> 0.14401353 | G15: =IF(G11="","",G14-G10) -> 0.16191247 | H15: =IF(H11="","",H14-H10) -> 0.10139852 | I15: =IF(I11="","",I14-I10) -> 0 | J15: =IF(J11="","",J14-J10) -> 0 | K15: =IF(K11="","",K14-K10) -> 0.043851682 | ... V15: =IF(V11="","",V14-V10) -> 0

Sheet Backtest by period
A1: aggregate | B1: valuation | C1: row | D1: V+1 | E1: V+2 | F1: total
A2: Example A - method 1 data | B2: 2023 | C2: period | D2: =IF($B2+1>2025,"",""&($B2+1)) -> 2024 | E2: =IF($B2+2>2025,"",""&($B2+2)) -> 2025
A3: Example A - method 1 data | B3: 2023 | C3: actual | D3: =IF(D2="","",SUMIFS(Detail!$N$2:$N$105,Detail!$A$2:$A$105,"M1",Detail!$B$2:$B$105,$B2,Detail!$D$2:$D$105,$B2+1)) -> 42408 | E3: =IF(E2="","",SUMIFS(Detail!$N$2:$N$105,Detail!$A$2:$A$105,"M1",Detail!$B$2:$B$105,$B2,Detail!$D$2:$D$105,$B2+2)) -> 0 | F3: =SUM(D3:E3) -> 42408
A4: Example A - method 1 data | B4: 2023 | C4: expected M1 | D4: =IF(D2="","",SUMIFS(Detail!$M$2:$M$105,Detail!$A$2:$A$105,"M1",Detail!$B$2:$B$105,$B2,Detail!$D$2:$D$105,$B2+1)) -> 128088.78 | E4: =IF(E2="","",SUMIFS(Detail!$M$2:$M$105,Detail!$A$2:$A$105,"M1",Detail!$B$2:$B$105,$B2,Detail!$D$2:$D$105,$B2+2)) -> 84367.924 | F4: =SUM(D4:E4) -> 212456.71
A5: Example A - method 1 data | B5: 2023 | C5: difference M1 | D5: =IF(D2="","",D4-D3) -> 85680.784 | E5: =IF(E2="","",E4-E3) -> 84367.924 | F5: =SUM(D5:E5) -> 170048.71
A6: Example A - method 1 data | B6: 2023 | C6: expected M2 | D6: =IF(D2="","",SUMIFS(Detail!$M$2:$M$105,Detail!$A$2:$A$105,"M2",Detail!$B$2:$B$105,$B2,Detail!$D$2:$D$105,$B2+1)) -> 105391.22 | E6: =IF(E2="","",SUMIFS(Detail!$M$2:$M$105,Detail!$A$2:$A$105,"M2",Detail!$B$2:$B$105,$B2,Detail!$D$2:$D$105,$B2+2)) -> 68185.684 | F6: =SUM(D6:E6) -> 173576.91
A7: Example A - method 1 data | B7: 2023 | C7: difference M2 | D7: =IF(D2="","",D6-D3) -> 62983.221 | E7: =IF(E2="","",E6-E3) -> 68185.684 | F7: =SUM(D7:E7) -> 131168.91
A10: Example A - method 1 data | B10: 2024 | C10: period | D10: =IF($B10+1>2025,"",""&($B10+1)) -> 2025 | E10: =IF($B10+2>2025,"",""&($B10+2))
A11: Example A - method 1 data | B11: 2024 | C11: actual | D11: =IF(D10="","",SUMIFS(Detail!$N$2:$N$105,Detail!$A$2:$A$105,"M1",Detail!$B$2:$B$105,$B10,Detail!$D$2:$D$105,$B10+1)) -> 1 | E11: =IF(E10="","",SUMIFS(Detail!$N$2:$N$105,Detail!$A$2:$A$105,"M1",Detail!$B$2:$B$105,$B10,Detail!$D$2:$D$105,$B10+2)) | F11: =SUM(D11:E11) -> 1
A12: Example A - method 1 data | B12: 2024 | C12: expected M1 | D12: =IF(D10="","",SUMIFS(Detail!$M$2:$M$105,Detail!$A$2:$A$105,"M1",Detail!$B$2:$B$105,$B10,Detail!$D$2:$D$105,$B10+1)) -> 78672.607 | E12: =IF(E10="","",SUMIFS(Detail!$M$2:$M$105,Detail!$A$2:$A$105,"M1",Detail!$B$2:$B$105,$B10,Detail!$D$2:$D$105,$B10+2)) | F12: =SUM(D12:E12) -> 78672.607
A13: Example A - method 1 data | B13: 2024 | C13: difference M1 | D13: =IF(D10="","",D12-D11) -> 78671.607 | E13: =IF(E10="","",E12-E11) | F13: =SUM(D13:E13) -> 78671.607
A14: Example A - method 1 data | B14: 2024 | C14: expected M2 | D14: =IF(D10="","",SUMIFS(Detail!$M$2:$M$105,Detail!$A$2:$A$105,"M2",Detail!$B$2:$B$105,$B10,Detail!$D$2:$D$105,$B10+1)) -> 55977.931 | E14: =IF(E10="","",SUMIFS(Detail!$M$2:$M$105,Detail!$A$2:$A$105,"M2",Detail!$B$2:$B$105,$B10,Detail!$D$2:$D$105,$B10+2)) | F14: =SUM(D14:E14) -> 55977.931
A15: Example A - method 1 data | B15: 2024 | C15: difference M2 | D15: =IF(D10="","",D14-D11) -> 55976.931 | E15: =IF(E10="","",E14-E11) | F15: =SUM(D15:E15) -> 55976.931

Sheet Metrics
A1: Metrics per aggregate x method x valuation (lower = better; 'all' pools both valuations)
A3: Huber threshold (money) | C3: 10000
A5: aggregate | B5: method | C5: valuation | D5: valuation filter | E5: n (AY x year) | F5: sum expected | G5: sum actual | H5: bias (exp - act) | I5: sum BE at valuation | J5: |bias| / BE | K5: SAE (sum |diff|) | L5: MAE | M5: SSE (sum diff^2) | N5: RMSE | O5: Pearson chi2 | P5: Huber loss | Q5: SAE / BE | R5: cum. MAE % of U | S5: cum. RMSE % pts | T5: rank |bias| | U5: rank SAE | V5: rank RMSE | W5: rank Pearson | X5: rank Huber | Y5: rank cum. MAE %
A6: Example A - method 1 data | B6: M1 | C6: 2023 | D6: 2023 | E6: =COUNTIFS(Detail!$U$2:$U$105,$A6,Detail!$A$2:$A$105,$B6,Detail!$B$2:$B$105,$D6) -> 34 | F6: =SUMIFS(Detail!$M$2:$M$105,Detail!$U$2:$U$105,$A6,Detail!$A$2:$A$105,$B6,Detail!$B$2:$B$105,$D6) -> 212456.71 | G6: =SUMIFS(Detail!$N$2:$N$105,Detail!$U$2:$U$105,$A6,Detail!$A$2:$A$105,$B6,Detail!$B$2:$B$105,$D6) -> 42408 | H6: =F6-G6 -> 170048.71 | I6: =SUMIFS(Detail!$I$2:$I$105,Detail!$U$2:$U$105,$A6,Detail!$A$2:$A$105,$B6,Detail!$B$2:$B$105,$D6,Detail!$E$2:$E$105,1) -> 367618 | J6: =IF(I6>0,ABS(H6)/I6,"") -> 0.46256905 | K6: =SUMIFS(Detail!$V$2:$V$105,Detail!$U$2:$U$105,$A6,Detail!$A$2:$A$105,$B6,Detail!$B$2:$B$105,$D6) -> 170048.71 | L6: =K6/E6 -> 5001.4326 | M6: =SUMIFS(Detail!$W$2:$W$105,Detail!$U$2:$U$105,$A6,Detail!$A$2:$A$105,$B6,Detail!$B$2:$B$105,$D6) -> 4.3860174e+09 | N6: =SQRT(M6/E6) -> 11357.839 | O6: =SUMIFS(Detail!$X$2:$X$105,Detail!$U$2:$U$105,$A6,Detail!$A$2:$A$105,$B6,Detail!$B$2:$B$105,$D6) -> 155442.79 | P6: =SUMIFS(Detail!$Y$2:$Y$105,Detail!$U$2:$U$105,$A6,Detail!$A$2:$A$105,$B6,Detail!$B$2:$B$105,$D6) -> 1.319704e+09 | Q6: =IF(I6>0,K6/I6,"") -> 0.46256905 | R6: =SUMIFS(Detail!$Z$2:$Z$105,Detail!$U$2:$U$105,$A6,Detail!$A$2:$A$105,$B6,Detail!$B$2:$B$105,$D6,Detail!$J$2:$J$105,">0")/SUMIFS(Detail!$J$2:$J$105,Detail!$U$2:$U$105,$A6,Detail!$A$2:$A$105,$B6,Detail!$B$2:$B$105,$D6,Detail!$J$2:$J$105,">0") -> 0.16310964 | S6: =SQRT(SUMIFS(Detail!$AA$2:$AA$105,Detail!$U$2:$U$105,$A6,Detail!$A$2:$A$105,$B6,Detail!$B$2:$B$105,$D6,Detail!$J$2:$J$105,">0")/COUNTIFS(Detail!$U$2:$U$105,$A6,Detail!$A$2:$A$105,$B6,Detail!$B$2:$B$105,$D6,Detail!$J$2:$J$105,">0")) -> 0.12346679 | T6: =SUMPRODUCT(($A$6:$A$11=$A6)*($C$6:$C$11=$C6)*($J$6:$J$11<J6))+1 -> 2 | U6: =SUMPRODUCT(($A$6:$A$11=$A6)*($C$6:$C$11=$C6)*($K$6:$K$11<K6))+1 -> 2 | V6: =SUMPRODUCT(($A$6:$A$11=$A6)*($C$6:$C$11=$C6)*($N$6:$N$11<N6))+1 -> 2 | W6: =SUMPRODUCT(($A$6:$A$11=$A6)*($C$6:$C$11=$C6)*($O$6:$O$11<O6))+1 -> 2 | X6: =SUMPRODUCT(($A$6:$A$11=$A6)*($C$6:$C$11=$C6)*($P$6:$P$11<P6))+1 -> 2 | Y6: =SUMPRODUCT(($A$6:$A$11=$A6)*($C$6:$C$11=$C6)*($R$6:$R$11<R6))+1 -> 2
A7: Example A - method 1 data | B7: M1 | C7: 2024 | D7: 2024 | E7: =COUNTIFS(Detail!$U$2:$U$105,$A7,Detail!$A$2:$A$105,$B7,Detail!$B$2:$B$105,$D7) -> 18 | F7: =SUMIFS(Detail!$M$2:$M$105,Detail!$U$2:$U$105,$A7,Detail!$A$2:$A$105,$B7,Detail!$B$2:$B$105,$D7) -> 78672.607 | G7: =SUMIFS(Detail!$N$2:$N$105,Detail!$U$2:$U$105,$A7,Detail!$A$2:$A$105,$B7,Detail!$B$2:$B$105,$D7) -> 1 | H7: =F7-G7 -> 78671.607 | I7: =SUMIFS(Detail!$I$2:$I$105,Detail!$U$2:$U$105,$A7,Detail!$A$2:$A$105,$B7,Detail!$B$2:$B$105,$D7,Detail!$E$2:$E$105,1) -> 312633 | J7: =IF(I7>0,ABS(H7)/I7,"") -> 0.25164204 | K7: =SUMIFS(Detail!$V$2:$V$105,Detail!$U$2:$U$105,$A7,Detail!$A$2:$A$105,$B7,Detail!$B$2:$B$105,$D7) -> 78671.607 | L7: =K7/E7 -> 4370.6448 | M7: =SUMIFS(Detail!$W$2:$W$105,Detail!$U$2:$U$105,$A7,Detail!$A$2:$A$105,$B7,Detail!$B$2:$B$105,$D7) -> 1.5552358e+09 | N7: =SQRT(M7/E7) -> 9295.267 | O7: =SUMIFS(Detail!$X$2:$X$105,Detail!$U$2:$U$105,$A7,Detail!$A$2:$A$105,$B7,Detail!$B$2:$B$105,$D7) -> 78670.609 | P7: =SUMIFS(Detail!$Y$2:$Y$105,Detail!$U$2:$U$105,$A7,Detail!$A$2:$A$105,$B7,Detail!$B$2:$B$105,$D7) -> 5.7847522e+08 | Q7: =IF(I7>0,K7/I7,"") -> 0.25164204 | R7: =SUMIFS(Detail!$Z$2:$Z$105,Detail!$U$2:$U$105,$A7,Detail!$A$2:$A$105,$B7,Detail!$B$2:$B$105,$D7,Detail!$J$2:$J$105,">0")/SUMIFS(Detail!$J$2:$J$105,Detail!$U$2:$U$105,$A7,Detail!$A$2:$A$105,$B7,Detail!$B$2:$B$105,$D7,Detail!$J$2:$J$105,">0") -> 0.10121828 | S7: =SQRT(SUMIFS(Detail!$AA$2:$AA$105,Detail!$U$2:$U$105,$A7,Detail!$A$2:$A$105,$B7,Detail!$B$2:$B$105,$D7,Detail!$J$2:$J$105,">0")/COUNTIFS(Detail!$U$2:$U$105,$A7,Detail!$A$2:$A$105,$B7,Detail!$B$2:$B$105,$D7,Detail!$J$2:$J$105,">0")) -> 0.080201208 | T7: =SUMPRODUCT(($A$6:$A$11=$A7)*($C$6:$C$11=$C7)*($J$6:$J$11<J7))+1 -> 2 | U7: =SUMPRODUCT(($A$6:$A$11=$A7)*($C$6:$C$11=$C7)*($K$6:$K$11<K7))+1 -> 2 | V7: =SUMPRODUCT(($A$6:$A$11=$A7)*($C$6:$C$11=$C7)*($N$6:$N$11<N7))+1 -> 2 | W7: =SUMPRODUCT(($A$6:$A$11=$A7)*($C$6:$C$11=$C7)*($O$6:$O$11<O7))+1 -> 2 | X7: =SUMPRODUCT(($A$6:$A$11=$A7)*($C$6:$C$11=$C7)*($P$6:$P$11<P7))+1 -> 2 | Y7: =SUMPRODUCT(($A$6:$A$11=$A7)*($C$6:$C$11=$C7)*($R$6:$R$11<R7))+1 -> 2
A8: Example A - method 1 data | B8: M1 | C8: all | D8: >0 | E8: =COUNTIFS(Detail!$U$2:$U$105,$A8,Detail!$A$2:$A$105,$B8,Detail!$B$2:$B$105,$D8) -> 52 | F8: =SUMIFS(Detail!$M$2:$M$105,Detail!$U$2:$U$105,$A8,Detail!$A$2:$A$105,$B8,Detail!$B$2:$B$105,$D8) -> 291129.32 | G8: =SUMIFS(Detail!$N$2:$N$105,Detail!$U$2:$U$105,$A8,Detail!$A$2:$A$105,$B8,Detail!$B$2:$B$105,$D8) -> 42409 | H8: =F8-G8 -> 248720.32 | I8: =SUMIFS(Detail!$I$2:$I$105,Detail!$U$2:$U$105,$A8,Detail!$A$2:$A$105,$B8,Detail!$B$2:$B$105,$D8,Detail!$E$2:$E$105,1) -> 680251 | J8: =IF(I8>0,ABS(H8)/I8,"") -> 0.36563021 | K8: =SUMIFS(Detail!$V$2:$V$105,Detail!$U$2:$U$105,$A8,Detail!$A$2:$A$105,$B8,Detail!$B$2:$B$105,$D8) -> 248720.32 | L8: =K8/E8 -> 4783.083 | M8: =SUMIFS(Detail!$W$2:$W$105,Detail!$U$2:$U$105,$A8,Detail!$A$2:$A$105,$B8,Detail!$B$2:$B$105,$D8) -> 5.9412532e+09 | N8: =SQRT(M8/E8) -> 10689.007 | O8: =SUMIFS(Detail!$X$2:$X$105,Detail!$U$2:$U$105,$A8,Detail!$A$2:$A$105,$B8,Detail!$B$2:$B$105,$D8) -> 234113.4 | P8: =SUMIFS(Detail!$Y$2:$Y$105,Detail!$U$2:$U$105,$A8,Detail!$A$2:$A$105,$B8,Detail!$B$2:$B$105,$D8) -> 1.8981793e+09 | Q8: =IF(I8>0,K8/I8,"") -> 0.36563021 | R8: =SUMIFS(Detail!$Z$2:$Z$105,Detail!$U$2:$U$105,$A8,Detail!$A$2:$A$105,$B8,Detail!$B$2:$B$105,$D8,Detail!$J$2:$J$105,">0")/SUMIFS(Detail!$J$2:$J$105,Detail!$U$2:$U$105,$A8,Detail!$A$2:$A$105,$B8,Detail!$B$2:$B$105,$D8,Detail!$J$2:$J$105,">0") -> 0.14259658 | S8: =SQRT(SUMIFS(Detail!$AA$2:$AA$105,Detail!$U$2:$U$105,$A8,Detail!$A$2:$A$105,$B8,Detail!$B$2:$B$105,$D8,Detail!$J$2:$J$105,">0")/COUNTIFS(Detail!$U$2:$U$105,$A8,Detail!$A$2:$A$105,$B8,Detail!$B$2:$B$105,$D8,Detail!$J$2:$J$105,">0")) -> 0.11042556 | T8: =SUMPRODUCT(($A$6:$A$11=$A8)*($C$6:$C$11=$C8)*($J$6:$J$11<J8))+1 -> 2 | U8: =SUMPRODUCT(($A$6:$A$11=$A8)*($C$6:$C$11=$C8)*($K$6:$K$11<K8))+1 -> 2 | V8: =SUMPRODUCT(($A$6:$A$11=$A8)*($C$6:$C$11=$C8)*($N$6:$N$11<N8))+1 -> 2 | W8: =SUMPRODUCT(($A$6:$A$11=$A8)*($C$6:$C$11=$C8)*($O$6:$O$11<O8))+1 -> 2 | X8: =SUMPRODUCT(($A$6:$A$11=$A8)*($C$6:$C$11=$C8)*($P$6:$P$11<P8))+1 -> 2 | Y8: =SUMPRODUCT(($A$6:$A$11=$A8)*($C$6:$C$11=$C8)*($R$6:$R$11<R8))+1 -> 2
A9: Example A - method 1 data | B9: M2 | C9: 2023 | D9: 2023 | E9: =COUNTIFS(Detail!$U$2:$U$105,$A9,Detail!$A$2:$A$105,$B9,Detail!$B$2:$B$105,$D9) -> 34 | F9: =SUMIFS(Detail!$M$2:$M$105,Detail!$U$2:$U$105,$A9,Detail!$A$2:$A$105,$B9,Detail!$B$2:$B$105,$D9) -> 173576.91 | G9: =SUMIFS(Detail!$N$2:$N$105,Detail!$U$2:$U$105,$A9,Detail!$A$2:$A$105,$B9,Detail!$B$2:$B$105,$D9) -> 42408 | H9: =F9-G9 -> 131168.91 | I9: =SUMIFS(Detail!$I$2:$I$105,Detail!$U$2:$U$105,$A9,Detail!$A$2:$A$105,$B9,Detail!$B$2:$B$105,$D9,Detail!$E$2:$E$105,1) -> 367618 | J9: =IF(I9>0,ABS(H9)/I9,"") -> 0.35680762 | K9: =SUMIFS(Detail!$V$2:$V$105,Detail!$U$2:$U$105,$A9,Detail!$A$2:$A$105,$B9,Detail!$B$2:$B$105,$D9) -> 131168.91 | L9: =K9/E9 -> 3857.909 | M9: =SUMIFS(Detail!$W$2:$W$105,Detail!$U$2:$U$105,$A9,Detail!$A$2:$A$105,$B9,Detail!$B$2:$B$105,$D9) -> 2.8478926e+09 | N9: =SQRT(M9/E9) -> 9152.1335 | O9: =SUMIFS(Detail!$X$2:$X$105,Detail!$U$2:$U$105,$A9,Detail!$A$2:$A$105,$B9,Detail!$B$2:$B$105,$D9) -> 123099.45 | P9: =SUMIFS(Detail!$Y$2:$Y$105,Detail!$U$2:$U$105,$A9,Detail!$A$2:$A$105,$B9,Detail!$B$2:$B$105,$D9) -> 9.6235555e+08 | Q9: =IF(I9>0,K9/I9,"") -> 0.35680762 | R9: =SUMIFS(Detail!$Z$2:$Z$105,Detail!$U$2:$U$105,$A9,Detail!$A$2:$A$105,$B9,Detail!$B$2:$B$105,$D9,Detail!$J$2:$J$105,">0")/SUMIFS(Detail!$J$2:$J$105,Detail!$U$2:$U$105,$A9,Detail!$A$2:$A$105,$B9,Detail!$B$2:$B$105,$D9,Detail!$J$2:$J$105,">0") -> 0.1238343 | S9: =SQRT(SUMIFS(Detail!$AA$2:$AA$105,Detail!$U$2:$U$105,$A9,Detail!$A$2:$A$105,$B9,Detail!$B$2:$B$105,$D9,Detail!$J$2:$J$105,">0")/COUNTIFS(Detail!$U$2:$U$105,$A9,Detail!$A$2:$A$105,$B9,Detail!$B$2:$B$105,$D9,Detail!$J$2:$J$105,">0")) -> 0.10317377 | T9: =SUMPRODUCT(($A$6:$A$11=$A9)*($C$6:$C$11=$C9)*($J$6:$J$11<J9))+1 -> 1 | U9: =SUMPRODUCT(($A$6:$A$11=$A9)*($C$6:$C$11=$C9)*($K$6:$K$11<K9))+1 -> 1 | V9: =SUMPRODUCT(($A$6:$A$11=$A9)*($C$6:$C$11=$C9)*($N$6:$N$11<N9))+1 -> 1 | W9: =SUMPRODUCT(($A$6:$A$11=$A9)*($C$6:$C$11=$C9)*($O$6:$O$11<O9))+1 -> 1 | X9: =SUMPRODUCT(($A$6:$A$11=$A9)*($C$6:$C$11=$C9)*($P$6:$P$11<P9))+1 -> 1 | Y9: =SUMPRODUCT(($A$6:$A$11=$A9)*($C$6:$C$11=$C9)*($R$6:$R$11<R9))+1 -> 1
A10: Example A - method 1 data | B10: M2 | C10: 2024 | D10: 2024 | E10: =COUNTIFS(Detail!$U$2:$U$105,$A10,Detail!$A$2:$A$105,$B10,Detail!$B$2:$B$105,$D10) -> 18 | F10: =SUMIFS(Detail!$M$2:$M$105,Detail!$U$2:$U$105,$A10,Detail!$A$2:$A$105,$B10,Detail!$B$2:$B$105,$D10) -> 55977.931 | G10: =SUMIFS(Detail!$N$2:$N$105,Detail!$U$2:$U$105,$A10,Detail!$A$2:$A$105,$B10,Detail!$B$2:$B$105,$D10) -> 1 | H10: =F10-G10 -> 55976.931 | I10: =SUMIFS(Detail!$I$2:$I$105,Detail!$U$2:$U$105,$A10,Detail!$A$2:$A$105,$B10,Detail!$B$2:$B$105,$D10,Detail!$E$2:$E$105,1) -> 312633 | J10: =IF(I10>0,ABS(H10)/I10,"") -> 0.17904997 | K10: =SUMIFS(Detail!$V$2:$V$105,Detail!$U$2:$U$105,$A10,Detail!$A$2:$A$105,$B10,Detail!$B$2:$B$105,$D10) -> 55976.931 | L10: =K10/E10 -> 3109.8295 | M10: =SUMIFS(Detail!$W$2:$W$105,Detail!$U$2:$U$105,$A10,Detail!$A$2:$A$105,$B10,Detail!$B$2:$B$105,$D10) -> 1.1210313e+09 | N10: =SQRT(M10/E10) -> 7891.7371 | O10: =SUMIFS(Detail!$X$2:$X$105,Detail!$U$2:$U$105,$A10,Detail!$A$2:$A$105,$B10,Detail!$B$2:$B$105,$D10) -> 55975.932 | P10: =SUMIFS(Detail!$Y$2:$Y$105,Detail!$U$2:$U$105,$A10,Detail!$A$2:$A$105,$B10,Detail!$B$2:$B$105,$D10) -> 4.0322109e+08 | Q10: =IF(I10>0,K10/I10,"") -> 0.17904997 | R10: =SUMIFS(Detail!$Z$2:$Z$105,Detail!$U$2:$U$105,$A10,Detail!$A$2:$A$105,$B10,Detail!$B$2:$B$105,$D10,Detail!$J$2:$J$105,">0")/SUMIFS(Detail!$J$2:$J$105,Detail!$U$2:$U$105,$A10,Detail!$A$2:$A$105,$B10,Detail!$B$2:$B$105,$D10,Detail!$J$2:$J$105,">0") -> 0.072019488 | S10: =SQRT(SUMIFS(Detail!$AA$2:$AA$105,Detail!$U$2:$U$105,$A10,Detail!$A$2:$A$105,$B10,Detail!$B$2:$B$105,$D10,Detail!$J$2:$J$105,">0")/COUNTIFS(Detail!$U$2:$U$105,$A10,Detail!$A$2:$A$105,$B10,Detail!$B$2:$B$105,$D10,Detail!$J$2:$J$105,">0")) -> 0.059883151 | T10: =SUMPRODUCT(($A$6:$A$11=$A10)*($C$6:$C$11=$C10)*($J$6:$J$11<J10))+1 -> 1 | U10: =SUMPRODUCT(($A$6:$A$11=$A10)*($C$6:$C$11=$C10)*($K$6:$K$11<K10))+1 -> 1 | V10: =SUMPRODUCT(($A$6:$A$11=$A10)*($C$6:$C$11=$C10)*($N$6:$N$11<N10))+1 -> 1 | W10: =SUMPRODUCT(($A$6:$A$11=$A10)*($C$6:$C$11=$C10)*($O$6:$O$11<O10))+1 -> 1 | X10: =SUMPRODUCT(($A$6:$A$11=$A10)*($C$6:$C$11=$C10)*($P$6:$P$11<P10))+1 -> 1 | Y10: =SUMPRODUCT(($A$6:$A$11=$A10)*($C$6:$C$11=$C10)*($R$6:$R$11<R10))+1 -> 1
A11: Example A - method 1 data | B11: M2 | C11: all | D11: >0 | E11: =COUNTIFS(Detail!$U$2:$U$105,$A11,Detail!$A$2:$A$105,$B11,Detail!$B$2:$B$105,$D11) -> 52 | F11: =SUMIFS(Detail!$M$2:$M$105,Detail!$U$2:$U$105,$A11,Detail!$A$2:$A$105,$B11,Detail!$B$2:$B$105,$D11) -> 229554.84 | G11: =SUMIFS(Detail!$N$2:$N$105,Detail!$U$2:$U$105,$A11,Detail!$A$2:$A$105,$B11,Detail!$B$2:$B$105,$D11) -> 42409 | H11: =F11-G11 -> 187145.84 | I11: =SUMIFS(Detail!$I$2:$I$105,Detail!$U$2:$U$105,$A11,Detail!$A$2:$A$105,$B11,Detail!$B$2:$B$105,$D11,Detail!$E$2:$E$105,1) -> 680251 | J11: =IF(I11>0,ABS(H11)/I11,"") -> 0.27511292 | K11: =SUMIFS(Detail!$V$2:$V$105,Detail!$U$2:$U$105,$A11,Detail!$A$2:$A$105,$B11,Detail!$B$2:$B$105,$D11) -> 187145.84 | L11: =K11/E11 -> 3598.9584 | M11: =SUMIFS(Detail!$W$2:$W$105,Detail!$U$2:$U$105,$A11,Detail!$A$2:$A$105,$B11,Detail!$B$2:$B$105,$D11) -> 3.9689239e+09 | N11: =SQRT(M11/E11) -> 8736.4443 | O11: =SUMIFS(Detail!$X$2:$X$105,Detail!$U$2:$U$105,$A11,Detail!$A$2:$A$105,$B11,Detail!$B$2:$B$105,$D11) -> 179075.38 | P11: =SUMIFS(Detail!$Y$2:$Y$105,Detail!$U$2:$U$105,$A11,Detail!$A$2:$A$105,$B11,Detail!$B$2:$B$105,$D11) -> 1.3655766e+09 | Q11: =IF(I11>0,K11/I11,"") -> 0.27511292 | R11: =SUMIFS(Detail!$Z$2:$Z$105,Detail!$U$2:$U$105,$A11,Detail!$A$2:$A$105,$B11,Detail!$B$2:$B$105,$D11,Detail!$J$2:$J$105,">0")/SUMIFS(Detail!$J$2:$J$105,Detail!$U$2:$U$105,$A11,Detail!$A$2:$A$105,$B11,Detail!$B$2:$B$105,$D11,Detail!$J$2:$J$105,">0") -> 0.10666098 | S11: =SQRT(SUMIFS(Detail!$AA$2:$AA$105,Detail!$U$2:$U$105,$A11,Detail!$A$2:$A$105,$B11,Detail!$B$2:$B$105,$D11,Detail!$J$2:$J$105,">0")/COUNTIFS(Detail!$U$2:$U$105,$A11,Detail!$A$2:$A$105,$B11,Detail!$B$2:$B$105,$D11,Detail!$J$2:$J$105,">0")) -> 0.090561494 | T11: =SUMPRODUCT(($A$6:$A$11=$A11)*($C$6:$C$11=$C11)*($J$6:$J$11<J11))+1 -> 1 | U11: =SUMPRODUCT(($A$6:$A$11=$A11)*($C$6:$C$11=$C11)*($K$6:$K$11<K11))+1 -> 1 | V11: =SUMPRODUCT(($A$6:$A$11=$A11)*($C$6:$C$11=$C11)*($N$6:$N$11<N11))+1 -> 1 | W11: =SUMPRODUCT(($A$6:$A$11=$A11)*($C$6:$C$11=$C11)*($O$6:$O$11<O11))+1 -> 1 | X11: =SUMPRODUCT(($A$6:$A$11=$A11)*($C$6:$C$11=$C11)*($P$6:$P$11<P11))+1 -> 1 | Y11: =SUMPRODUCT(($A$6:$A$11=$A11)*($C$6:$C$11=$C11)*($R$6:$R$11<R11))+1 -> 1
A14: best method (rank 1) per metric
A15: metric | B15: what it measures | C15: 2023 | D15: 2024 | E15: all
A16: |bias| / BE | B16: total over- or under-projection of payments, scaled by the reserve | C16: =IFERROR(INDEX($B$6:$B$11,MATCH(1,INDEX(($A$6:$A$11="Example A - method 1 data")*($C$6:$C$11=2023)*($T$6:$T$11=1),0),0)),"") -> M2 | D16: =IFERROR(INDEX($B$6:$B$11,MATCH(1,INDEX(($A$6:$A$11="Example A - method 1 data")*($C$6:$C$11=2024)*($T$6:$T$11=1),0),0)),"") -> M2 | E16: =IFERROR(INDEX($B$6:$B$11,MATCH(1,INDEX(($A$6:$A$11="Example A - method 1 data")*($C$6:$C$11="all")*($T$6:$T$11=1),0),0)),"") -> M2
A17: SAE | B17: sum of absolute differences per AY and year (money) | C17: =IFERROR(INDEX($B$6:$B$11,MATCH(1,INDEX(($A$6:$A$11="Example A - method 1 data")*($C$6:$C$11=2023)*($U$6:$U$11=1),0),0)),"") -> M2 | D17: =IFERROR(INDEX($B$6:$B$11,MATCH(1,INDEX(($A$6:$A$11="Example A - method 1 data")*($C$6:$C$11=2024)*($U$6:$U$11=1),0),0)),"") -> M2 | E17: =IFERROR(INDEX($B$6:$B$11,MATCH(1,INDEX(($A$6:$A$11="Example A - method 1 data")*($C$6:$C$11="all")*($U$6:$U$11=1),0),0)),"") -> M2
A18: RMSE | B18: root mean squared difference (money) - penalises big misses | C18: =IFERROR(INDEX($B$6:$B$11,MATCH(1,INDEX(($A$6:$A$11="Example A - method 1 data")*($C$6:$C$11=2023)*($V$6:$V$11=1),0),0)),"") -> M2 | D18: =IFERROR(INDEX($B$6:$B$11,MATCH(1,INDEX(($A$6:$A$11="Example A - method 1 data")*($C$6:$C$11=2024)*($V$6:$V$11=1),0),0)),"") -> M2 | E18: =IFERROR(INDEX($B$6:$B$11,MATCH(1,INDEX(($A$6:$A$11="Example A - method 1 data")*($C$6:$C$11="all")*($V$6:$V$11=1),0),0)),"") -> M2
A19: Pearson chi2 | B19: sum diff^2 / expected - classic actual vs expected test | C19: =IFERROR(INDEX($B$6:$B$11,MATCH(1,INDEX(($A$6:$A$11="Example A - method 1 data")*($C$6:$C$11=2023)*($W$6:$W$11=1),0),0)),"") -> M2 | D19: =IFERROR(INDEX($B$6:$B$11,MATCH(1,INDEX(($A$6:$A$11="Example A - method 1 data")*($C$6:$C$11=2024)*($W$6:$W$11=1),0),0)),"") -> M2 | E19: =IFERROR(INDEX($B$6:$B$11,MATCH(1,INDEX(($A$6:$A$11="Example A - method 1 data")*($C$6:$C$11="all")*($W$6:$W$11=1),0),0)),"") -> M2
A20: Huber | B20: squared for small, linear for big differences - robust to outliers | C20: =IFERROR(INDEX($B$6:$B$11,MATCH(1,INDEX(($A$6:$A$11="Example A - method 1 data")*($C$6:$C$11=2023)*($X$6:$X$11=1),0),0)),"") -> M2 | D20: =IFERROR(INDEX($B$6:$B$11,MATCH(1,INDEX(($A$6:$A$11="Example A - method 1 data")*($C$6:$C$11=2024)*($X$6:$X$11=1),0),0)),"") -> M2 | E20: =IFERROR(INDEX($B$6:$B$11,MATCH(1,INDEX(($A$6:$A$11="Example A - method 1 data")*($C$6:$C$11="all")*($X$6:$X$11=1),0),0)),"") -> M2
A21: cum. MAE % of U | B21: U-weighted mean |difference| in cumulative % of U (pattern basis) | C21: =IFERROR(INDEX($B$6:$B$11,MATCH(1,INDEX(($A$6:$A$11="Example A - method 1 data")*($C$6:$C$11=2023)*($Y$6:$Y$11=1),0),0)),"") -> M2 | D21: =IFERROR(INDEX($B$6:$B$11,MATCH(1,INDEX(($A$6:$A$11="Example A - method 1 data")*($C$6:$C$11=2024)*($Y$6:$Y$11=1),0),0)),"") -> M2 | E21: =IFERROR(INDEX($B$6:$B$11,MATCH(1,INDEX(($A$6:$A$11="Example A - method 1 data")*($C$6:$C$11="all")*($Y$6:$Y$11=1),0),0)),"") -> M2

Sheet Detail
A1: method | B1: valuation | C1: AY | D1: year | E1: years after valuation | F1: tenor at valuation | G1: tenor in year | H1: paid at valuation | I1: BE at valuation | J1: U at valuation | K1: pattern at valuation tenor | L1: pattern at tenor in year | M1: expected paid in year | N1: actual paid in year | O1: difference paid (exp - act) | P1: expected cum. paid | Q1: actual cum. paid | R1: expected cum. % of U | S1: actual cum. % of U | T1: difference % (exp - act) | U1: aggregate | V1: abs difference | W1: squared difference | X1: Pearson term (diff^2 / expected) | Y1: Huber loss | Z1: abs cum. difference | AA1: squared difference % (U > 0)
A2: M1 | B2: 2023 | C2: 2007 | D2: 2024 | E2: =D2-B2 -> 1 | F2: =B2-C2+1 -> 17 | G2: =D2-C2+1 -> 18 | H2: =INDEX(Data!$B$3:$T$21,MATCH(C2,Data!$A$3:$A$21,0),MATCH(B2,Data!$B$2:$T$2,0)) -> 1382 | I2: =INDEX(Data!$B$25:$T$43,MATCH(C2,Data!$A$3:$A$21,0),MATCH(B2,Data!$B$2:$T$2,0)) -> 0 | J2: =H2+I2 -> 1382 | K2: =INDEX('pattern input'!$B$2:$AO$5,MATCH(A2&"_"&B2,'pattern input'!$A$2:$A$5,0),F2) -> 0.99396181 | L2: =INDEX('pattern input'!$B$2:$AO$5,MATCH(A2&"_"&B2,'pattern input'!$A$2:$A$5,0),G2) -> 1 | M2: =IF(K2>=1,0,I2*(L2-INDEX('pattern input'!$B$2:$AO$5,MATCH(A2&"_"&B2,'pattern input'!$A$2:$A$5,0),G2-1))/(1-K2)) -> 0 | N2: =INDEX(Data!$B$3:$T$21,MATCH(C2,Data!$A$3:$A$21,0),MATCH(D2,Data!$B$2:$T$2,0))-INDEX(Data!$B$3:$T$21,MATCH(C2,Data!$A$3:$A$21,0),MATCH(D2-1,Data!$B$2:$T$2,0)) -> 0 | O2: =M2-N2 -> 0 | P2: =IF(K2>=1,H2+I2,H2+I2*(L2-K2)/(1-K2)) -> 1382 | Q2: =INDEX(Data!$B$3:$T$21,MATCH(C2,Data!$A$3:$A$21,0),MATCH(D2,Data!$B$2:$T$2,0)) -> 1382 | R2: =IF(J2>0,P2/J2,"") -> 1 | S2: =IF(J2>0,Q2/J2,"") -> 1 | T2: =IF(J2>0,R2-S2,"") -> 0 | U2: Example A - method 1 data | V2: =ABS(O2) -> 0 | W2: =O2^2 -> 0 | X2: =IF(M2>0,O2^2/M2,0) -> 0 | Y2: =IF(V2<=Metrics!$C$3,0.5*O2^2,Metrics!$C$3*(V2-0.5*Metrics!$C$3)) -> 0 | Z2: =ABS(P2-Q2) -> 0 | AA2: =IF(J2>0,T2^2,0) -> 0
A3: M1 | B3: 2023 | C3: 2007 | D3: 2025 | E3: =D3-B3 -> 2 | F3: =B3-C3+1 -> 17 | G3: =D3-C3+1 -> 19 | H3: =INDEX(Data!$B$3:$T$21,MATCH(C3,Data!$A$3:$A$21,0),MATCH(B3,Data!$B$2:$T$2,0)) -> 1382 | I3: =INDEX(Data!$B$25:$T$43,MATCH(C3,Data!$A$3:$A$21,0),MATCH(B3,Data!$B$2:$T$2,0)) -> 0 | J3: =H3+I3 -> 1382 | K3: =INDEX('pattern input'!$B$2:$AO$5,MATCH(A3&"_"&B3,'pattern input'!$A$2:$A$5,0),F3) -> 0.99396181 | L3: =INDEX('pattern input'!$B$2:$AO$5,MATCH(A3&"_"&B3,'pattern input'!$A$2:$A$5,0),G3) -> 1 | M3: =IF(K3>=1,0,I3*(L3-INDEX('pattern input'!$B$2:$AO$5,MATCH(A3&"_"&B3,'pattern input'!$A$2:$A$5,0),G3-1))/(1-K3)) -> 0 | N3: =INDEX(Data!$B$3:$T$21,MATCH(C3,Data!$A$3:$A$21,0),MATCH(D3,Data!$B$2:$T$2,0))-INDEX(Data!$B$3:$T$21,MATCH(C3,Data!$A$3:$A$21,0),MATCH(D3-1,Data!$B$2:$T$2,0)) -> 0 | O3: =M3-N3 -> 0 | P3: =IF(K3>=1,H3+I3,H3+I3*(L3-K3)/(1-K3)) -> 1382 | Q3: =INDEX(Data!$B$3:$T$21,MATCH(C3,Data!$A$3:$A$21,0),MATCH(D3,Data!$B$2:$T$2,0)) -> 1382 | R3: =IF(J3>0,P3/J3,"") -> 1 | S3: =IF(J3>0,Q3/J3,"") -> 1 | T3: =IF(J3>0,R3-S3,"") -> 0 | U3: Example A - method 1 data | V3: =ABS(O3) -> 0 | W3: =O3^2 -> 0 | X3: =IF(M3>0,O3^2/M3,0) -> 0 | Y3: =IF(V3<=Metrics!$C$3,0.5*O3^2,Metrics!$C$3*(V3-0.5*Metrics!$C$3)) -> 0 | Z3: =ABS(P3-Q3) -> 0 | AA3: =IF(J3>0,T3^2,0) -> 0
A4: M1 | B4: 2023 | C4: 2008 | D4: 2024 | E4: =D4-B4 -> 1 | F4: =B4-C4+1 -> 16 | G4: =D4-C4+1 -> 17 | H4: =INDEX(Data!$B$3:$T$21,MATCH(C4,Data!$A$3:$A$21,0),MATCH(B4,Data!$B$2:$T$2,0)) -> 9472 | I4: =INDEX(Data!$B$25:$T$43,MATCH(C4,Data!$A$3:$A$21,0),MATCH(B4,Data!$B$2:$T$2,0)) -> 3 | J4: =H4+I4 -> 9475 | K4: =INDEX('pattern input'!$B$2:$AO$5,MATCH(A4&"_"&B4,'pattern input'!$A$2:$A$5,0),F4) -> 0.98755745 | L4: =INDEX('pattern input'!$B$2:$AO$5,MATCH(A4&"_"&B4,'pattern input'!$A$2:$A$5,0),G4) -> 0.99396181 | M4: =IF(K4>=1,0,I4*(L4-INDEX('pattern input'!$B$2:$AO$5,MATCH(A4&"_"&B4,'pattern input'!$A$2:$A$5,0),G4-1))/(1-K4)) -> 1.5441431 | N4: =INDEX(Data!$B$3:$T$21,MATCH(C4,Data!$A$3:$A$21,0),MATCH(D4,Data!$B$2:$T$2,0))-INDEX(Data!$B$3:$T$21,MATCH(C4,Data!$A$3:$A$21,0),MATCH(D4-1,Data!$B$2:$T$2,0)) -> 0 | O4: =M4-N4 -> 1.5441431 | P4: =IF(K4>=1,H4+I4,H4+I4*(L4-K4)/(1-K4)) -> 9473.5441 | Q4: =INDEX(Data!$B$3:$T$21,MATCH(C4,Data!$A$3:$A$21,0),MATCH(D4,Data!$B$2:$T$2,0)) -> 9472 | R4: =IF(J4>0,P4/J4,"") -> 0.99984635 | S4: =IF(J4>0,Q4/J4,"") -> 0.99968338 | T4: =IF(J4>0,R4-S4,"") -> 0.00016297025 | U4: Example A - method 1 data | V4: =ABS(O4) -> 1.5441431 | W4: =O4^2 -> 2.384378 | X4: =IF(M4>0,O4^2/M4,0) -> 1.5441431 | Y4: =IF(V4<=Metrics!$C$3,0.5*O4^2,Metrics!$C$3*(V4-0.5*Metrics!$C$3)) -> 1.192189 | Z4: =ABS(P4-Q4) -> 1.5441431 | AA4: =IF(J4>0,T4^2,0) -> 2.6559303e-08
A5: M1 | B5: 2023 | C5: 2008 | D5: 2025 | E5: =D5-B5 -> 2 | F5: =B5-C5+1 -> 16 | G5: =D5-C5+1 -> 18 | H5: =INDEX(Data!$B$3:$T$21,MATCH(C5,Data!$A$3:$A$21,0),MATCH(B5,Data!$B$2:$T$2,0)) -> 9472 | I5: =INDEX(Data!$B$25:$T$43,MATCH(C5,Data!$A$3:$A$21,0),MATCH(B5,Data!$B$2:$T$2,0)) -> 3 | J5: =H5+I5 -> 9475 | K5: =INDEX('pattern input'!$B$2:$AO$5,MATCH(A5&"_"&B5,'pattern input'!$A$2:$A$5,0),F5) -> 0.98755745 | L5: =INDEX('pattern input'!$B$2:$AO$5,MATCH(A5&"_"&B5,'pattern input'!$A$2:$A$5,0),G5) -> 1 | M5: =IF(K5>=1,0,I5*(L5-INDEX('pattern input'!$B$2:$AO$5,MATCH(A5&"_"&B5,'pattern input'!$A$2:$A$5,0),G5-1))/(1-K5)) -> 1.4558569 | N5: =INDEX(Data!$B$3:$T$21,MATCH(C5,Data!$A$3:$A$21,0),MATCH(D5,Data!$B$2:$T$2,0))-INDEX(Data!$B$3:$T$21,MATCH(C5,Data!$A$3:$A$21,0),MATCH(D5-1,Data!$B$2:$T$2,0)) -> 0 | O5: =M5-N5 -> 1.4558569 | P5: =IF(K5>=1,H5+I5,H5+I5*(L5-K5)/(1-K5)) -> 9475 | Q5: =INDEX(Data!$B$3:$T$21,MATCH(C5,Data!$A$3:$A$21,0),MATCH(D5,Data!$B$2:$T$2,0)) -> 9472 | R5: =IF(J5>0,P5/J5,"") -> 1 | S5: =IF(J5>0,Q5/J5,"") -> 0.99968338 | T5: =IF(J5>0,R5-S5,"") -> 0.00031662269 | U5: Example A - method 1 data | V5: =ABS(O5) -> 1.4558569 | W5: =O5^2 -> 2.1195192 | X5: =IF(M5>0,O5^2/M5,0) -> 1.4558569 | Y5: =IF(V5<=Metrics!$C$3,0.5*O5^2,Metrics!$C$3*(V5-0.5*Metrics!$C$3)) -> 1.0597596 | Z5: =ABS(P5-Q5) -> 3 | AA5: =IF(J5>0,T5^2,0) -> 1.0024993e-07
A6: M1 | B6: 2023 | C6: 2009 | D6: 2024 | E6: =D6-B6 -> 1 | F6: =B6-C6+1 -> 15 | G6: =D6-C6+1 -> 16 | H6: =INDEX(Data!$B$3:$T$21,MATCH(C6,Data!$A$3:$A$21,0),MATCH(B6,Data!$B$2:$T$2,0)) -> 8788 | I6: =INDEX(Data!$B$25:$T$43,MATCH(C6,Data!$A$3:$A$21,0),MATCH(B6,Data!$B$2:$T$2,0)) -> 0 | J6: =H6+I6 -> 8788 | K6: =INDEX('pattern input'!$B$2:$AO$5,MATCH(A6&"_"&B6,'pattern input'!$A$2:$A$5,0),F6) -> 0.98073963 | L6: =INDEX('pattern input'!$B$2:$AO$5,MATCH(A6&"_"&B6,'pattern input'!$A$2:$A$5,0),G6) -> 0.98755745 | M6: =IF(K6>=1,0,I6*(L6-INDEX('pattern input'!$B$2:$AO$5,MATCH(A6&"_"&B6,'pattern input'!$A$2:$A$5,0),G6-1))/(1-K6)) -> 0 | N6: =INDEX(Data!$B$3:$T$21,MATCH(C6,Data!$A$3:$A$21,0),MATCH(D6,Data!$B$2:$T$2,0))-INDEX(Data!$B$3:$T$21,MATCH(C6,Data!$A$3:$A$21,0),MATCH(D6-1,Data!$B$2:$T$2,0)) -> 0 | O6: =M6-N6 -> 0 | P6: =IF(K6>=1,H6+I6,H6+I6*(L6-K6)/(1-K6)) -> 8788 | Q6: =INDEX(Data!$B$3:$T$21,MATCH(C6,Data!$A$3:$A$21,0),MATCH(D6,Data!$B$2:$T$2,0)) -> 8788 | R6: =IF(J6>0,P6/J6,"") -> 1 | S6: =IF(J6>0,Q6/J6,"") -> 1 | T6: =IF(J6>0,R6-S6,"") -> 0 | U6: Example A - method 1 data | V6: =ABS(O6) -> 0 | W6: =O6^2 -> 0 | X6: =IF(M6>0,O6^2/M6,0) -> 0 | Y6: =IF(V6<=Metrics!$C$3,0.5*O6^2,Metrics!$C$3*(V6-0.5*Metrics!$C$3)) -> 0 | Z6: =ABS(P6-Q6) -> 0 | AA6: =IF(J6>0,T6^2,0) -> 0
A7: M1 | B7: 2023 | C7: 2009 | D7: 2025 | E7: =D7-B7 -> 2 | F7: =B7-C7+1 -> 15 | G7: =D7-C7+1 -> 17 | H7: =INDEX(Data!$B$3:$T$21,MATCH(C7,Data!$A$3:$A$21,0),MATCH(B7,Data!$B$2:$T$2,0)) -> 8788 | I7: =INDEX(Data!$B$25:$T$43,MATCH(C7,Data!$A$3:$A$21,0),MATCH(B7,Data!$B$2:$T$2,0)) -> 0 | J7: =H7+I7 -> 8788 | K7: =INDEX('pattern input'!$B$2:$AO$5,MATCH(A7&"_"&B7,'pattern input'!$A$2:$A$5,0),F7) -> 0.98073963 | L7: =INDEX('pattern input'!$B$2:$AO$5,MATCH(A7&"_"&B7,'pattern input'!$A$2:$A$5,0),G7) -> 0.99396181 | M7: =IF(K7>=1,0,I7*(L7-INDEX('pattern input'!$B$2:$AO$5,MATCH(A7&"_"&B7,'pattern input'!$A$2:$A$5,0),G7-1))/(1-K7)) -> 0 | N7: =INDEX(Data!$B$3:$T$21,MATCH(C7,Data!$A$3:$A$21,0),MATCH(D7,Data!$B$2:$T$2,0))-INDEX(Data!$B$3:$T$21,MATCH(C7,Data!$A$3:$A$21,0),MATCH(D7-1,Data!$B$2:$T$2,0)) -> 0 | O7: =M7-N7 -> 0 | P7: =IF(K7>=1,H7+I7,H7+I7*(L7-K7)/(1-K7)) -> 8788 | Q7: =INDEX(Data!$B$3:$T$21,MATCH(C7,Data!$A$3:$A$21,0),MATCH(D7,Data!$B$2:$T$2,0)) -> 8788 | R7: =IF(J7>0,P7/J7,"") -> 1 | S7: =IF(J7>0,Q7/J7,"") -> 1 | T7: =IF(J7>0,R7-S7,"") -> 0 | U7: Example A - method 1 data | V7: =ABS(O7) -> 0 | W7: =O7^2 -> 0 | X7: =IF(M7>0,O7^2/M7,0) -> 0 | Y7: =IF(V7<=Metrics!$C$3,0.5*O7^2,Metrics!$C$3*(V7-0.5*Metrics!$C$3)) -> 0 | Z7: =ABS(P7-Q7) -> 0 | AA7: =IF(J7>0,T7^2,0) -> 0
A8: M1 | B8: 2023 | C8: 2010 | D8: 2024 | E8: =D8-B8 -> 1 | F8: =B8-C8+1 -> 14 | G8: =D8-C8+1 -> 15 | H8: =INDEX(Data!$B$3:$T$21,MATCH(C8,Data!$A$3:$A$21,0),MATCH(B8,Data!$B$2:$T$2,0)) -> 8854 | I8: =INDEX(Data!$B$25:$T$43,MATCH(C8,Data!$A$3:$A$21,0),MATCH(B8,Data!$B$2:$T$2,0)) -> 0 | J8: =H8+I8 -> 8854 | K8: =INDEX('pattern input'!$B$2:$AO$5,MATCH(A8&"_"&B8,'pattern input'!$A$2:$A$5,0),F8) -> 0.97345126 | L8: =INDEX('pattern input'!$B$2:$AO$5,MATCH(A8&"_"&B8,'pattern input'!$A$2:$A$5,0),G8) -> 0.98073963 | M8: =IF(K8>=1,0,I8*(L8-INDEX('pattern input'!$B$2:$AO$5,MATCH(A8&"_"&B8,'pattern input'!$A$2:$A$5,0),G8-1))/(1-K8)) -> 0 | N8: =INDEX(Data!$B$3:$T$21,MATCH(C8,Data!$A$3:$A$21,0),MATCH(D8,Data!$B$2:$T$2,0))-INDEX(Data!$B$3:$T$21,MATCH(C8,Data!$A$3:$A$21,0),MATCH(D8-1,Data!$B$2:$T$2,0)) -> 0 | O8: =M8-N8 -> 0 | P8: =IF(K8>=1,H8+I8,H8+I8*(L8-K8)/(1-K8)) -> 8854 | Q8: =INDEX(Data!$B$3:$T$21,MATCH(C8,Data!$A$3:$A$21,0),MATCH(D8,Data!$B$2:$T$2,0)) -> 8854 | R8: =IF(J8>0,P8/J8,"") -> 1 | S8: =IF(J8>0,Q8/J8,"") -> 1 | T8: =IF(J8>0,R8-S8,"") -> 0 | U8: Example A - method 1 data | V8: =ABS(O8) -> 0 | W8: =O8^2 -> 0 | X8: =IF(M8>0,O8^2/M8,0) -> 0 | Y8: =IF(V8<=Metrics!$C$3,0.5*O8^2,Metrics!$C$3*(V8-0.5*Metrics!$C$3)) -> 0 | Z8: =ABS(P8-Q8) -> 0 | AA8: =IF(J8>0,T8^2,0) -> 0
A9: M1 | B9: 2023 | C9: 2010 | D9: 2025 | E9: =D9-B9 -> 2 | F9: =B9-C9+1 -> 14 | G9: =D9-C9+1 -> 16 | H9: =INDEX(Data!$B$3:$T$21,MATCH(C9,Data!$A$3:$A$21,0),MATCH(B9,Data!$B$2:$T$2,0)) -> 8854 | I9: =INDEX(Data!$B$25:$T$43,MATCH(C9,Data!$A$3:$A$21,0),MATCH(B9,Data!$B$2:$T$2,0)) -> 0 | J9: =H9+I9 -> 8854 | K9: =INDEX('pattern input'!$B$2:$AO$5,MATCH(A9&"_"&B9,'pattern input'!$A$2:$A$5,0),F9) -> 0.97345126 | L9: =INDEX('pattern input'!$B$2:$AO$5,MATCH(A9&"_"&B9,'pattern input'!$A$2:$A$5,0),G9) -> 0.98755745 | M9: =IF(K9>=1,0,I9*(L9-INDEX('pattern input'!$B$2:$AO$5,MATCH(A9&"_"&B9,'pattern input'!$A$2:$A$5,0),G9-1))/(1-K9)) -> 0 | N9: =INDEX(Data!$B$3:$T$21,MATCH(C9,Data!$A$3:$A$21,0),MATCH(D9,Data!$B$2:$T$2,0))-INDEX(Data!$B$3:$T$21,MATCH(C9,Data!$A$3:$A$21,0),MATCH(D9-1,Data!$B$2:$T$2,0)) -> 0 | O9: =M9-N9 -> 0 | P9: =IF(K9>=1,H9+I9,H9+I9*(L9-K9)/(1-K9)) -> 8854 | Q9: =INDEX(Data!$B$3:$T$21,MATCH(C9,Data!$A$3:$A$21,0),MATCH(D9,Data!$B$2:$T$2,0)) -> 8854 | R9: =IF(J9>0,P9/J9,"") -> 1 | S9: =IF(J9>0,Q9/J9,"") -> 1 | T9: =IF(J9>0,R9-S9,"") -> 0 | U9: Example A - method 1 data | V9: =ABS(O9) -> 0 | W9: =O9^2 -> 0 | X9: =IF(M9>0,O9^2/M9,0) -> 0 | Y9: =IF(V9<=Metrics!$C$3,0.5*O9^2,Metrics!$C$3*(V9-0.5*Metrics!$C$3)) -> 0 | Z9: =ABS(P9-Q9) -> 0 | AA9: =IF(J9>0,T9^2,0) -> 0
A10: M1 | B10: 2023 | C10: 2011 | D10: 2024 | E10: =D10-B10 -> 1 | F10: =B10-C10+1 -> 13 | G10: =D10-C10+1 -> 14 | H10: =INDEX(Data!$B$3:$T$21,MATCH(C10,Data!$A$3:$A$21,0),MATCH(B10,Data!$B$2:$T$2,0)) -> 26889 | I10: =INDEX(Data!$B$25:$T$43,MATCH(C10,Data!$A$3:$A$21,0),MATCH(B10,Data!$B$2:$T$2,0)) -> 0 | J10: =H10+I10 -> 26889 | K10: =INDEX('pattern input'!$B$2:$AO$5,MATCH(A10&"_"&B10,'pattern input'!$A$2:$A$5,0),F10) -> 0.96562252 | L10: =INDEX('pattern input'!$B$2:$AO$5,MATCH(A10&"_"&B10,'pattern input'!$A$2:$A$5,0),G10) -> 0.97345126 | M10: =IF(K10>=1,0,I10*(L10-INDEX('pattern input'!$B$2:$AO$5,MATCH(A10&"_"&B10,'pattern input'!$A$2:$A$5,0),G10-1))/(1-K10)) -> 0 | N10: =INDEX(Data!$B$3:$T$21,MATCH(C10,Data!$A$3:$A$21,0),MATCH(D10,Data!$B$2:$T$2,0))-INDEX(Data!$B$3:$T$21,MATCH(C10,Data!$A$3:$A$21,0),MATCH(D10-1,Data!$B$2:$T$2,0)) -> 0 | O10: =M10-N10 -> 0 | P10: =IF(K10>=1,H10+I10,H10+I10*(L10-K10)/(1-K10)) -> 26889 | Q10: =INDEX(Data!$B$3:$T$21,MATCH(C10,Data!$A$3:$A$21,0),MATCH(D10,Data!$B$2:$T$2,0)) -> 26889 | R10: =IF(J10>0,P10/J10,"") -> 1 | S10: =IF(J10>0,Q10/J10,"") -> 1 | T10: =IF(J10>0,R10-S10,"") -> 0 | U10: Example A - method 1 data | V10: =ABS(O10) -> 0 | W10: =O10^2 -> 0 | X10: =IF(M10>0,O10^2/M10,0) -> 0 | Y10: =IF(V10<=Metrics!$C$3,0.5*O10^2,Metrics!$C$3*(V10-0.5*Metrics!$C$3)) -> 0 | Z10: =ABS(P10-Q10) -> 0 | AA10: =IF(J10>0,T10^2,0) -> 0
A11: M1 | B11: 2023 | C11: 2011 | D11: 2025 | E11: =D11-B11 -> 2 | F11: =B11-C11+1 -> 13 | G11: =D11-C11+1 -> 15 | H11: =INDEX(Data!$B$3:$T$21,MATCH(C11,Data!$A$3:$A$21,0),MATCH(B11,Data!$B$2:$T$2,0)) -> 26889 | I11: =INDEX(Data!$B$25:$T$43,MATCH(C11,Data!$A$3:$A$21,0),MATCH(B11,Data!$B$2:$T$2,0)) -> 0 | J11: =H11+I11 -> 26889 | K11: =INDEX('pattern input'!$B$2:$AO$5,MATCH(A11&"_"&B11,'pattern input'!$A$2:$A$5,0),F11) -> 0.96562252 | L11: =INDEX('pattern input'!$B$2:$AO$5,MATCH(A11&"_"&B11,'pattern input'!$A$2:$A$5,0),G11) -> 0.98073963 | M11: =IF(K11>=1,0,I11*(L11-INDEX('pattern input'!$B$2:$AO$5,MATCH(A11&"_"&B11,'pattern input'!$A$2:$A$5,0),G11-1))/(1-K11)) -> 0 | N11: =INDEX(Data!$B$3:$T$21,MATCH(C11,Data!$A$3:$A$21,0),MATCH(D11,Data!$B$2:$T$2,0))-INDEX(Data!$B$3:$T$21,MATCH(C11,Data!$A$3:$A$21,0),MATCH(D11-1,Data!$B$2:$T$2,0)) -> 0 | O11: =M11-N11 -> 0 | P11: =IF(K11>=1,H11+I11,H11+I11*(L11-K11)/(1-K11)) -> 26889 | Q11: =INDEX(Data!$B$3:$T$21,MATCH(C11,Data!$A$3:$A$21,0),MATCH(D11,Data!$B$2:$T$2,0)) -> 26889 | R11: =IF(J11>0,P11/J11,"") -> 1 | S11: =IF(J11>0,Q11/J11,"") -> 1 | T11: =IF(J11>0,R11-S11,"") -> 0 | U11: Example A - method 1 data | V11: =ABS(O11) -> 0 | W11: =O11^2 -> 0 | X11: =IF(M11>0,O11^2/M11,0) -> 0 | Y11: =IF(V11<=Metrics!$C$3,0.5*O11^2,Metrics!$C$3*(V11-0.5*Metrics!$C$3)) -> 0 | Z11: =ABS(P11-Q11) -> 0 | AA11: =IF(J11>0,T11^2,0) -> 0
